Workbook
Name ChemicalNames: OFFSET('Chemical Data'!$A$5,0,0,MAX(1,COUNTA('Chemical Data'!$A$5:$A$500)),1)

Sheet Model
B1: Secondary Poisoning Model
B2: Steady-state bioaccumulation of (ionisable) pharmaceuticals in aquatic, terrestrial and subterranean food chains.
B4: How to use | J4: Cell key
B5: 1. Chemical: choose Lookup and pick a pharmaceutical from the list, or choose Manual Input and fill in column E. | J5: Input – yellow cells can be edited
B6: 2. Environment: enter the water and/or soil concentration and conditions. | J6: Calculated – do not overwrite
B7: 3. Food chain: set class, environment, diet, blood type, body mass and internal pH for up to four trophic levels (None = level not modelled). | J7: Main result
B8: 4. Results (top right) update automatically. Intermediate calculations are below row 60 and do not need input. | J8: '–' = not applicable / not available
B11: 1 CHEMICAL | J11: RESULTS | R11: TIME-COURSE (for the chart)
B12: Chemical input | D12: Lookup | E12: Lookup = 'Chemical Data' sheet; Manual Input = your own values in column E | J12: Output | K12: Unit | L12: TL 1 | M12: TL 2 | N12: TL 3 | O12: TL 4 | R12: Quantity | S12: TL 1 | T12: TL 2 | U12: TL 3 | V12: TL 4
B13: Pharmaceutical (Lookup) | D13: Metoprolol | F13: Drop-down list of 61 pharmaceuticals | J13: Organism | K13: – | L13: =IF(D$46="None","–",D$46) -> Algae | M13: =IF(E$46="None","–",E$46) -> Crustaceans | N13: =IF(F$46="None","–",F$46) -> Fish | O13: =IF(G$46="None","–",G$46) -> Birds | R13: Level modelled | S13: =ISNUMBER(L$14) -> TRUE | T13: =ISNUMBER(M$14) -> TRUE | U13: =ISNUMBER(N$14) -> TRUE | V13: =ISNUMBER(O$14) -> TRUE
B14: Property | C14: Unit | D14: Database | E14: Manual input | F14: Value used | G14: Source | H14: Notes | J14: Steady-state concentration | K14: µg/kg ww | L14: =IF(OR(D$46="None",$D$31<>"OK"),"-",IFERROR((L24*$D$35+L25*$D$72+L26*$D$73+L27*IF(D$48="Detritus",$D$71,0))/L35,"-")) -> 0.0663785 | M14: =IF(OR(E$46="None",$D$31<>"OK"),"-",IFERROR((M24*$D$35+M25*$D$72+M26*$D$73+M27*IF(E$48="Detritus",$D$71,L14))/M35,"-")) -> 0.18130765 | N14: =IF(OR(F$46="None",$D$31<>"OK"),"-",IFERROR((N24*$D$35+N25*$D$72+N26*$D$73+N27*IF(F$48="Detritus",$D$71,M14))/N35,"-")) -> 0.22165911 | O14: =IF(OR(G$46="None",$D$31<>"OK"),"-",IFERROR((O24*$D$35+O25*$D$72+O26*$D$73+O27*IF(G$48="Detritus",$D$71,N14))/O35,"-")) -> 0.0025971749 | R14: Uptake from water/air/pore water (µg/kg/d) | S14: =IF(S13,L24*$D$35+L25*$D$72+L26*$D$73,0) -> 0.015104867 | T14: =IF(T13,M24*$D$35+M25*$D$72+M26*$D$73,0) -> 0.18166013 | U14: =IF(U13,N24*$D$35+N25*$D$72+N26*$D$73,0) -> 0.018166013 | V14: =IF(V13,O24*$D$35+O25*$D$72+O26*$D$73,0) -> 0
B15: Name | C15: – | D15: =IF(ISNUMBER($D$64),INDEX('Chemical Data'!$A$5:$A$500,$D$64),"–") -> Metoprolol | E15: My compound | F15: =IF($D$12="Manual Input",IF(E15="","(manual compound)",E15),D15) -> Metoprolol | G15: =IF($D$12="Manual Input","Manual","PubChem") -> PubChem | H15: Manual example values = diclofenac | J15: BAF relative to water | K15: L/kg | L15: =IF(AND(ISNUMBER(L14),N($D$35)>0),L14/$D$35,"–") -> 0.663785 | M15: =IF(AND(ISNUMBER(M14),N($D$35)>0),M14/$D$35,"–") -> 1.8130765 | N15: =IF(AND(ISNUMBER(N14),N($D$35)>0),N14/$D$35,"–") -> 2.2165911 | O15: =IF(AND(ISNUMBER(O14),N($D$35)>0),O14/$D$35,"–") -> 0.025971749 | R15: k1,in (d⁻¹) | S15: =IF(S13,L27,0) -> 0 | T15: =IF(T13,M27,0) -> 0.0029568944 | U15: =IF(U13,N27,0) -> 0.0024864711 | V15: =IF(V13,O27,0) -> 0.028808553
B16: log Kow, neutral species | C16: – | D16: =IF(ISNUMBER($D$64),INDEX('Chemical Data'!$E$5:$E$500,$D$64),"–") -> 1.6132 | E16: 4.3641 | F16: =IF($D$12="Manual Input",E16,D16) -> 1.6132 | G16: =IF($D$12="Manual Input","Manual","RDKit (Crippen)") -> RDKit (Crippen) | J16: BAF relative to soil | K16: kg/kg | L16: =IF(AND(ISNUMBER(L14),N($D$38)>0),L14/$D$38,"–") -> – | M16: =IF(AND(ISNUMBER(M14),N($D$38)>0),M14/$D$38,"–") -> – | N16: =IF(AND(ISNUMBER(N14),N($D$38)>0),N14/$D$38,"–") -> – | O16: =IF(AND(ISNUMBER(O14),N($D$38)>0),O14/$D$38,"–") -> – | R16: Σk_out (d⁻¹) | S16: =IF(S13,L35,1) -> 0.22755661 | T16: =IF(T13,M35,1) -> 1.0030267 | U16: =IF(U13,N35,1) -> 0.08398856 | V16: =IF(V13,O35,1) -> 2.4587017
B17: log Kow, ionised species | C17: – | D17: =IF(ISNUMBER($D$64),INDEX('Chemical Data'!$F$5:$F$500,$D$64),"–") -> 0.587 | E17: 3.0294 | F17: =IF($D$12="Manual Input",E17,D17) -> 0.587 | G17: =IF($D$12="Manual Input","Manual","RDKit (Crippen)") -> RDKit (Crippen) | H17: Ionised structure | J17: BMF relative to the level below | K17: – | L17: – | M17: =IF(AND(ISNUMBER(M14),ISNUMBER(L14),OR(E$48="Herbivore",E$48="Carnivore")),IF(L14>0,M14/L14,"–"),"–") -> 2.7314213 | N17: =IF(AND(ISNUMBER(N14),ISNUMBER(M14),OR(F$48="Herbivore",F$48="Carnivore")),IF(M14>0,N14/M14,"–"),"–") -> 1.222558 | O17: =IF(AND(ISNUMBER(O14),ISNUMBER(N14),OR(G$48="Herbivore",G$48="Carnivore")),IF(N14>0,O14/N14,"–"),"–") -> 0.011716978 | R17: Feeds on soil (detritus) | S17: =D$48="Detritus" -> FALSE | T17: =E$48="Detritus" -> FALSE | U17: =F$48="Detritus" -> FALSE | V17: =G$48="Detritus" -> FALSE
B18: log Koa | C18: – | D18: =IF(ISNUMBER($D$64),INDEX('Chemical Data'!$G$5:$G$500,$D$64),"–") -> 8.4 | E18: 9.3 | F18: =IF($D$12="Manual Input",E18,D18) -> 8.4 | G18: =IF($D$12="Manual Input","Manual","CompTox") -> CompTox | J18: TMF of the food chain | K18: – | L18: =IF(SUM($D$134:$G$134)>=2,10^((SUM($D$134:$G$134)*SUMPRODUCT($D$135:$G$135,$D$136:$G$136)-SUM($D$135:$G$135)*SUM($D$136:$G$136))/(SUM($D$134:$G$134)*SUMPRODUCT($D$135:$G$135,$D$135:$G$135)-SUM($D$135:$G$135)^2)),"–") -> 0.38589493 | R18: exp(−Σk_out·Δt) | S18: =EXP(-S16*$S$22) -> 0.98196017 | T18: =EXP(-T16*$S$22) -> 0.92289286 | U18: =EXP(-U16*$S$22) -> 0.99330344 | V18: =EXP(-V16*$S$22) -> 0.8214402
B19: log Kaw | C19: – | D19: =IFERROR(D16-D18,"–") -> -6.7868 | E19: (calculated) | F19: =IFERROR($F$16-$F$18,"–") -> -6.7868 | G19: (calculated) | H19: log Kow − log Koa | J19: Time to 95 % of steady state | K19: d | L19: =IF(ISNUMBER(L14),IF(COUNTIF(S$25:S$1025,"<"&0.95*L14)>1000,"> "&ROUND($S$20,3),COUNTIF(S$25:S$1025,"<"&0.95*L14)*$S$22),"–") -> 13.2 | M19: =IF(ISNUMBER(M14),IF(COUNTIF(T$25:T$1025,"<"&0.95*M14)>1000,"> "&ROUND($S$20,3),COUNTIF(T$25:T$1025,"<"&0.95*M14)*$S$22),"–") -> 3.04 | N19: =IF(ISNUMBER(N14),IF(COUNTIF(U$25:U$1025,"<"&0.95*N14)>1000,"> "&ROUND($S$20,3),COUNTIF(U$25:U$1025,"<"&0.95*N14)*$S$22),"–") -> 35.76 | O19: =IF(ISNUMBER(O14),IF(COUNTIF(V$25:V$1025,"<"&0.95*O14)>1000,"> "&ROUND($S$20,3),COUNTIF(V$25:V$1025,"<"&0.95*O14)*$S$22),"–") -> 36.16 | R19: (1 − exp(−Σk_out·Δt))/Σk_out | S19: =(1-S18)/S16 -> 0.079276218 | T19: =(1-T18)/T16 -> 0.07687447 | U19: =(1-U18)/U16 -> 0.079731838 | V19: =(1-V18)/V16 -> 0.072623612
B20: pKa (most relevant) | C20: – | D20: =IF(ISNUMBER($D$64),INDEX('Chemical Data'!$J$5:$J$500,$D$64),"–") -> 9.93 | E20: 4.13 | F20: =IF($D$12="Manual Input",E20,D20) -> 9.93 | G20: =IF($D$12="Manual Input","Manual","CompTox") -> CompTox | H20: pKa matching the ionisation type | J20: Status | K20: – | L20: =IF(D$46="None","Not modelled",IF($D$31<>"OK","Check chemical",IF(OR(NOT(ISNUMBER(D$50)),N(D$50)<=0),"Enter a body mass",IF(AND(D$47="Terrestrial",NOT(ISNUMBER(D112))),"Invalid class",IF(ISNUMBER(L14),"OK","Check inputs"))))) -> OK | M20: =IF(E$46="None","Not modelled",IF($D$31<>"OK","Check chemical",IF(OR(NOT(ISNUMBER(E$50)),N(E$50)<=0),"Enter a body mass",IF(AND(E$47="Terrestrial",NOT(ISNUMBER(E112))),"Invalid class",IF(AND(E$48<>"Detritus",NOT(ISNUMBER(L14))),"No food level",IF(ISNUMBER(M14),"OK","Check inputs")))))) -> OK | N20: =IF(F$46="None","Not modelled",IF($D$31<>"OK","Check chemical",IF(OR(NOT(ISNUMBER(F$50)),N(F$50)<=0),"Enter a body mass",IF(AND(F$47="Terrestrial",NOT(ISNUMBER(F112))),"Invalid class",IF(AND(F$48<>"Detritus",NOT(ISNUMBER(M14))),"No food level",IF(ISNUMBER(N14),"OK","Check inputs")))))) -> OK | O20: =IF(G$46="None","Not modelled",IF($D$31<>"OK","Check chemical",IF(OR(NOT(ISNUMBER(G$50)),N(G$50)<=0),"Enter a body mass",IF(AND(G$47="Terrestrial",NOT(ISNUMBER(G112))),"Invalid class",IF(AND(G$48<>"Detritus",NOT(ISNUMBER(N14))),"No food level",IF(ISNUMBER(O14),"OK","Check inputs")))))) -> OK | R20: Length used (d) | S20: =IF(ISNUMBER($D$57),$D$57,S21) -> 80 | T20: Exact exponential step for constant inputs
B21: Ionisation type | C21: – | D21: =IF(ISNUMBER($D$64),INDEX('Chemical Data'!$D$5:$D$500,$D$64),"–") -> Basic | E21: Acidic | F21: =IF($D$12="Manual Input",E21,D21) -> Basic | G21: =IF($D$12="Manual Input","Manual","RDKit") -> RDKit | H21: Acidic, Basic or Neutral | J21: Status: Invalid class = terrestrial organisms must be Birds, Mammals or Insects; No food level = level below not modelled. | R21: Auto length (d) | S21: =IF(SUM(S23:V23)>0,CEILING(4*SUM(S23:V23)/10^INT(LOG10(4*SUM(S23:V23))),1)*10^INT(LOG10(4*SUM(S23:V23))),1) -> 80 | T21: rounded up from 4 × Σ(1/Σk_out)
B22: Ionising functional group | C22: – | D22: =IF(ISNUMBER($D$64),INDEX('Chemical Data'!$C$5:$C$500,$D$64),"–") -> 2° Amine | E22: Carboxylic Acid | F22: =IF($D$12="Manual Input",E22,D22) -> 2° Amine | G22: =IF($D$12="Manual Input","Manual","RDKit") -> RDKit | H22: Selects the ionised-species descriptors | J22: RATE CONSTANTS (Equation 1) | R22: Time step Δt (d) | S22: =S20/1000 -> 0.08
B23: Biotransformation half-life (10 g fish) | C23: d | D23: =IF(ISNUMBER($D$64),INDEX('Chemical Data'!$K$5:$K$500,$D$64),"–") -> 0.325 | E23: 6.13 | F23: =IF($D$12="Manual Input",E23,D23) -> 0.325 | G23: =IF($D$12="Manual Input","Manual","EPI Suite") -> EPI Suite | H23: Only used when biotransformation is On | J23: Process | K23: Symbol (unit) | L23: TL 1 | M23: TL 2 | N23: TL 3 | O23: TL 4 | R23: 1/Σk_out (d) | S23: =IF(S13,1/S16,0) -> 4.3945108 | T23: =IF(T13,1/T16,0) -> 0.99698246 | U23: =IF(U13,1/U16,0) -> 11.906383 | V23: =IF(V13,1/V16,0) -> 0.40671872
B24: Abraham solute descriptors (neutral species) | H24: =IF($D$74,"Measured: UFZ-LSERD; QSBR: from SMILES","Not available: K_iW II = I, no urinary excretion") -> Measured: UFZ-LSERD; QSBR: from SMILES | J24: Uptake from water | K24: k0,in-aq (L/kg/d) | L24: =IF(D$85,IFERROR(IF(D$47="Aquatic",D$50^-0.25/($L$106+D103/$D$66+1/D106),0),"n/a"),"–") -> 0.15104867 | M24: =IF(E$85,IFERROR(IF(E$47="Aquatic",E$50^-0.25/($L$106+E103/$D$66+1/E106),0),"n/a"),"–") -> 1.8166013 | N24: =IF(F$85,IFERROR(IF(F$47="Aquatic",F$50^-0.25/($L$106+F103/$D$66+1/F106),0),"n/a"),"–") -> 0.18166013 | O24: =IF(G$85,IFERROR(IF(G$47="Aquatic",G$50^-0.25/($L$106+G103/$D$66+1/G106),0),"n/a"),"–") -> 0 | R24: t (d) | S24: ="TL 1: "&L13 -> TL 1: Algae | T24: ="TL 2: "&M13 -> TL 2: Crustaceans | U24: ="TL 3: "&N13 -> TL 3: Fish | V24: ="TL 4: "&O13 -> TL 4: Birds
B25: E – excess molar refraction | C25: – | D25: =IF(ISNUMBER($D$64),IF(ISNUMBER(INDEX('Chemical Data'!$L$5:$L$500,$D$64)),INDEX('Chemical Data'!$L$5:$L$500,$D$64),IF(AND($D$55="Yes",ISNUMBER(INDEX('Chemical Data'!$R$5:$R$500,$D$64))),INDEX('Chemical Data'!$R$5:$R$500,$D$64),"-")),"–") -> 1.162 | E25: 1.9657143 | F25: =IF($D$12="Manual Input",IF(ISNUMBER(E25),E25,"-"),D25) -> 1.162 | G25: =IF($D$12="Manual Input",IF(ISNUMBER(E25),"Manual","Not given"),IF(NOT(ISNUMBER($D$64)),"–",IF(ISNUMBER(INDEX('Chemical Data'!$L$5:$L$500,$D$64)),"Measured",IF(AND($D$55="Yes",ISNUMBER(INDEX('Chemical Data'!$R$5:$R$500,$D$64))),"QSBR","Not available")))) -> Measured | H25: Used by the pp-LFERs, K_BA and the kidney block | J25: Uptake from air | K25: k0,in-air (L/kg/d) | L25: =IF(D$85,IFERROR(IF(D$47="Terrestrial",IF(ISNUMBER(D116),D$50^-0.25/(D113+$L$112/$D$75+1/D116),"n/a"),0),"n/a"),"–") -> 0 | M25: =IF(E$85,IFERROR(IF(E$47="Terrestrial",IF(ISNUMBER(E116),E$50^-0.25/(E113+$L$112/$D$75+1/E116),"n/a"),0),"n/a"),"–") -> 0 | N25: =IF(F$85,IFERROR(IF(F$47="Terrestrial",IF(ISNUMBER(F116),F$50^-0.25/(F113+$L$112/$D$75+1/F116),"n/a"),0),"n/a"),"–") -> 0 | O25: =IF(G$85,IFERROR(IF(G$47="Terrestrial",IF(ISNUMBER(G116),G$50^-0.25/(G113+$L$112/$D$75+1/G116),"n/a"),0),"n/a"),"–") -> 0.0017178527 | R25: 0 | S25: =IF(S$13,0,NA()) -> 0 | T25: =IF(T$13,0,NA()) -> 0 | U25: =IF(U$13,0,NA()) -> 0 | V25: =IF(V$13,0,NA()) -> 0
B26: S – dipolarity / polarisability | C26: – | D26: =IF(ISNUMBER($D$64),IF(ISNUMBER(INDEX('Chemical Data'!$M$5:$M$500,$D$64)),INDEX('Chemical Data'!$M$5:$M$500,$D$64),IF(AND($D$55="Yes",ISNUMBER(INDEX('Chemical Data'!$S$5:$S$500,$D$64))),INDEX('Chemical Data'!$S$5:$S$500,$D$64),"-")),"–") -> 1.3 | E26: 1.6742857 | F26: =IF($D$12="Manual Input",IF(ISNUMBER(E26),E26,"-"),D26) -> 1.3 | G26: =IF($D$12="Manual Input",IF(ISNUMBER(E26),"Manual","Not given"),IF(NOT(ISNUMBER($D$64)),"–",IF(ISNUMBER(INDEX('Chemical Data'!$M$5:$M$500,$D$64)),"Measured",IF(AND($D$55="Yes",ISNUMBER(INDEX('Chemical Data'!$S$5:$S$500,$D$64))),"QSBR","Not available")))) -> Measured | J26: Uptake from pore water | K26: k0,in-pw (L/kg/d) | L26: =IF(D$85,IFERROR(IF(D$47="Subterranean",D$50^-0.25/($L$106+D103/$D$68),0),"n/a"),"–") -> 0 | M26: =IF(E$85,IFERROR(IF(E$47="Subterranean",E$50^-0.25/($L$106+E103/$D$68),0),"n/a"),"–") -> 0 | N26: =IF(F$85,IFERROR(IF(F$47="Subterranean",F$50^-0.25/($L$106+F103/$D$68),0),"n/a"),"–") -> 0 | O26: =IF(G$85,IFERROR(IF(G$47="Subterranean",G$50^-0.25/($L$106+G103/$D$68),0),"n/a"),"–") -> 0 | R26: =R25+$S$22 -> 0.08 | S26: =IF(S$13,S25*S$18+(S$14+S$15*IF(S$17,$D$71,0))*S$19,NA()) -> 0.0011974567 | T26: =IF(T$13,T25*T$18+(T$14+T$15*IF(T$17,$D$71,(S25+S26)/2))*T$19,NA()) -> 0.013965163 | U26: =IF(U$13,U25*U$18+(U$14+U$15*IF(U$17,$D$71,(T25+T26)/2))*U$19,NA()) -> 0.0014497939 | V26: =IF(V$13,V25*V$18+(V$14+V$15*IF(V$17,$D$71,(U25+U26)/2))*V$19,NA()) -> 1.5166158e-06
B27: A – H-bond acidity | C27: – | D27: =IF(ISNUMBER($D$64),IF(ISNUMBER(INDEX('Chemical Data'!$N$5:$N$500,$D$64)),INDEX('Chemical Data'!$N$5:$N$500,$D$64),IF(AND($D$55="Yes",ISNUMBER(INDEX('Chemical Data'!$T$5:$T$500,$D$64))),INDEX('Chemical Data'!$T$5:$T$500,$D$64),"-")),"–") -> 0.156 | E27: 0.60571429 | F27: =IF($D$12="Manual Input",IF(ISNUMBER(E27),E27,"-"),D27) -> 0.156 | G27: =IF($D$12="Manual Input",IF(ISNUMBER(E27),"Manual","Not given"),IF(NOT(ISNUMBER($D$64)),"–",IF(ISNUMBER(INDEX('Chemical Data'!$N$5:$N$500,$D$64)),"Measured",IF(AND($D$55="Yes",ISNUMBER(INDEX('Chemical Data'!$T$5:$T$500,$D$64))),"QSBR","Not available")))) -> Measured | J27: Assimilation from food | K27: k1,in (d⁻¹) | L27: =IF(D$85,IFERROR(IFERROR(IF(D$48="Detritus",(D88/(1-D88))*(1/$D$70)*D107,0),0),"n/a"),"–") -> 0 | M27: =IF(E$85,IFERROR(IFERROR(IF(E$48="Detritus",(E88/(1-E88))*(1/$D$70)*E107,(E88/(1-E88))*(1/D102)*E107),0),"n/a"),"–") -> 0.0029568944 | N27: =IF(F$85,IFERROR(IFERROR(IF(F$48="Detritus",(F88/(1-F88))*(1/$D$70)*F107,(F88/(1-F88))*(1/E102)*F107),0),"n/a"),"–") -> 0.0024864711 | O27: =IF(G$85,IFERROR(IFERROR(IF(G$48="Detritus",(G88/(1-G88))*(1/$D$70)*G107,(G88/(1-G88))*(1/F102)*G107),0),"n/a"),"–") -> 0.028808553 | R27: =R26+$S$22 -> 0.16 | S27: =IF(S$13,S26*S$18+(S$14+S$15*IF(S$17,$D$71,0))*S$19,NA()) -> 0.0023733115 | T27: =IF(T$13,T26*T$18+(T$14+T$15*IF(T$17,$D$71,(S26+S27)/2))*T$19,NA()) -> 0.026853781 | U27: =IF(U$13,U26*U$18+(U$14+U$15*IF(U$17,$D$71,(T26+T27)/2))*U$19,NA()) -> 0.0028925411 | V27: =IF(V$13,V26*V$18+(V$14+V$15*IF(V$17,$D$71,(U26+U27)/2))*V$19,NA()) -> 5.7882851e-06
B28: B – H-bond basicity | C28: – | D28: =IF(ISNUMBER($D$64),IF(ISNUMBER(INDEX('Chemical Data'!$O$5:$O$500,$D$64)),INDEX('Chemical Data'!$O$5:$O$500,$D$64),IF(AND($D$55="Yes",ISNUMBER(INDEX('Chemical Data'!$U$5:$U$500,$D$64))),INDEX('Chemical Data'!$U$5:$U$500,$D$64),"-")),"–") -> 1.696 | E28: 0.83857143 | F28: =IF($D$12="Manual Input",IF(ISNUMBER(E28),E28,"-"),D28) -> 1.696 | G28: =IF($D$12="Manual Input",IF(ISNUMBER(E28),"Manual","Not given"),IF(NOT(ISNUMBER($D$64)),"–",IF(ISNUMBER(INDEX('Chemical Data'!$O$5:$O$500,$D$64)),"Measured",IF(AND($D$55="Yes",ISNUMBER(INDEX('Chemical Data'!$U$5:$U$500,$D$64))),"QSBR","Not available")))) -> Measured | J28: Excretion to water | K28: k0,out-aq (d⁻¹) | L28: =IF(D$85,IFERROR(IF(D$47="Aquatic",(1/D102)*L24,0),"n/a"),"–") -> 0.12085985 | M28: =IF(E$85,IFERROR(IF(E$47="Aquatic",(1/E102)*M24,0),"n/a"),"–") -> 0.98105938 | N28: =IF(F$85,IFERROR(IF(F$47="Aquatic",(1/F102)*N24,0),"n/a"),"–") -> 0.081574323 | O28: =IF(G$85,IFERROR(IF(G$47="Aquatic",(1/G102)*O24,0),"n/a"),"–") -> 0 | R28: =R27+$S$22 -> 0.24 | S28: =IF(S$13,S27*S$18+(S$14+S$15*IF(S$17,$D$71,0))*S$19,NA()) -> 0.003527954 | T28: =IF(T$13,T27*T$18+(T$14+T$15*IF(T$17,$D$71,(S27+S28)/2))*T$19,NA()) -> 0.03874886 | U28: =IF(U$13,U27*U$18+(U$14+U$15*IF(U$17,$D$71,(T27+T28)/2))*U$19,NA()) -> 0.0043280836 | V28: =IF(V$13,V27*V$18+(V$14+V$15*IF(V$17,$D$71,(U27+U28)/2))*V$19,NA()) -> 1.2308158e-05
B29: V – McGowan volume | C29: – | D29: =IF(ISNUMBER($D$64),IF(ISNUMBER(INDEX('Chemical Data'!$P$5:$P$500,$D$64)),INDEX('Chemical Data'!$P$5:$P$500,$D$64),IF(AND($D$55="Yes",ISNUMBER(INDEX('Chemical Data'!$V$5:$V$500,$D$64))),INDEX('Chemical Data'!$V$5:$V$500,$D$64),"-")),"–") -> 2.2604 | E29: 2.025 | F29: =IF($D$12="Manual Input",IF(ISNUMBER(E29),E29,"-"),D29) -> 2.2604 | G29: =IF($D$12="Manual Input",IF(ISNUMBER(E29),"Manual","Not given"),IF(NOT(ISNUMBER($D$64)),"–",IF(ISNUMBER(INDEX('Chemical Data'!$P$5:$P$500,$D$64)),"Measured",IF(AND($D$55="Yes",ISNUMBER(INDEX('Chemical Data'!$V$5:$V$500,$D$64))),"QSBR","Not available")))) -> Measured | J29: Exhalation to air | K29: k0,out-air (d⁻¹) | L29: =IF(D$85,IFERROR(IF(D$47="Terrestrial",IFERROR((1/$D$75)*L25,"n/a"),0),"n/a"),"–") -> 0 | M29: =IF(E$85,IFERROR(IF(E$47="Terrestrial",IFERROR((1/$D$75)*M25,"n/a"),0),"n/a"),"–") -> 0 | N29: =IF(F$85,IFERROR(IF(F$47="Terrestrial",IFERROR((1/$D$75)*N25,"n/a"),0),"n/a"),"–") -> 0 | O29: =IF(G$85,IFERROR(IF(G$47="Terrestrial",IFERROR((1/$D$75)*O25,"n/a"),0),"n/a"),"–") -> 5.1442955e-13 | R29: =R28+$S$22 -> 0.32 | S29: =IF(S$13,S28*S$18+(S$14+S$15*IF(S$17,$D$71,0))*S$19,NA()) -> 0.0046617671 | T29: =IF(T$13,T28*T$18+(T$14+T$15*IF(T$17,$D$71,(S28+S29)/2))*T$19,NA()) -> 0.049727004 | U29: =IF(U$13,U28*U$18+(U$14+U$15*IF(U$17,$D$71,(T28+T29)/2))*U$19,NA()) -> 0.0057562801 | V29: =IF(V$13,V28*V$18+(V$14+V$15*IF(V$17,$D$71,(U28+U29)/2))*V$19,NA()) -> 2.0659574e-05
B30: L – log hexadecane–air partition coefficient | C30: – | D30: =IF(ISNUMBER($D$64),IF(ISNUMBER(INDEX('Chemical Data'!$Q$5:$Q$500,$D$64)),INDEX('Chemical Data'!$Q$5:$Q$500,$D$64),IF(AND($D$55="Yes",ISNUMBER(INDEX('Chemical Data'!$W$5:$W$500,$D$64))),INDEX('Chemical Data'!$W$5:$W$500,$D$64),"-")),"–") -> 9.83 | E30: 11.025 | F30: =IF($D$12="Manual Input",IF(ISNUMBER(E30),E30,"-"),D30) -> 9.83 | G30: =IF($D$12="Manual Input",IF(ISNUMBER(E30),"Manual","Not given"),IF(NOT(ISNUMBER($D$64)),"–",IF(ISNUMBER(INDEX('Chemical Data'!$Q$5:$Q$500,$D$64)),"Measured",IF(AND($D$55="Yes",ISNUMBER(INDEX('Chemical Data'!$W$5:$W$500,$D$64))),"QSBR","Not available")))) -> Measured | H30: Manual input: leave blank if unknown | J30: Excretion to pore water | K30: k0,out-pw (d⁻¹) | L30: =IF(D$85,IFERROR(IF(D$47="Subterranean",L26/D102,0),"n/a"),"–") -> 0 | M30: =IF(E$85,IFERROR(IF(E$47="Subterranean",M26/E102,0),"n/a"),"–") -> 0 | N30: =IF(F$85,IFERROR(IF(F$47="Subterranean",N26/F102,0),"n/a"),"–") -> 0 | O30: =IF(G$85,IFERROR(IF(G$47="Subterranean",O26/G102,0),"n/a"),"–") -> 0 | R30: =R29+$S$22 -> 0.4 | S30: =IF(S$13,S29*S$18+(S$14+S$15*IF(S$17,$D$71,0))*S$19,NA()) -> 0.0057751263 | T30: =IF(T$13,T29*T$18+(T$14+T$15*IF(T$17,$D$71,(S29+S30)/2))*T$19,NA()) -> 0.059858909 | U30: =IF(U$13,U29*U$18+(U$14+U$15*IF(U$17,$D$71,(T29+T30)/2))*U$19,NA()) -> 0.0071770052 | V30: =IF(V$13,V29*V$18+(V$14+V$15*IF(V$17,$D$71,(U29+U30)/2))*V$19,NA()) -> 3.0499993e-05
B31: Input check | D31: =IF($D$12="Manual Input",IF(OR(E16="",E18="",E21=""),"Manual input: enter log Kow, log Koa and ionisation type",IF(AND(E21<>"Neutral",OR(E17="",E20="",E22="")),"Manual input: enter ionised log Kow, pKa and functional group",IF(AND($D$56="On",E23=""),"Manual input: enter a half-life (biotransformation is On)","OK"))),IF(ISNUMBER($D$64),"OK","Pick a pharmaceutical from the list")) -> OK | J31: Excretion with urine | K31: k1,out-urine (d⁻¹) | L31: =IF(D$85,IFERROR(IF(OR(D$47="Terrestrial",D$47="Subterranean"),IFERROR(D120*D125*(1-D130)/D126,0),0),"n/a"),"–") -> 0 | M31: =IF(E$85,IFERROR(IF(OR(E$47="Terrestrial",E$47="Subterranean"),IFERROR(E120*E125*(1-E130)/E126,0),0),"n/a"),"–") -> 0 | N31: =IF(F$85,IFERROR(IF(OR(F$47="Terrestrial",F$47="Subterranean"),IFERROR(F120*F125*(1-F130)/F126,0),0),"n/a"),"–") -> 0 | O31: =IF(G$85,IFERROR(IF(OR(G$47="Terrestrial",G$47="Subterranean"),IFERROR(G120*G125*(1-G130)/G126,0),0),"n/a"),"–") -> 2.4469979 | R31: =R30+$S$22 -> 0.48 | S31: =IF(S$13,S30*S$18+(S$14+S$15*IF(S$17,$D$71,0))*S$19,NA()) -> 0.0068684007 | T31: =IF(T$13,T30*T$18+(T$14+T$15*IF(T$17,$D$71,(S30+S31)/2))*T$19,NA()) -> 0.069209823 | U31: =IF(U$13,U30*U$18+(U$14+U$15*IF(U$17,$D$71,(T30+T31)/2))*U$19,NA()) -> 0.0085901476 | V31: =IF(V$13,V30*V$18+(V$14+V$15*IF(V$17,$D$71,(U30+U31)/2))*V$19,NA()) -> 4.154779e-05
J32: Egestion with faeces | K32: k1,out-fae (d⁻¹) | L32: =IF(D$85,IFERROR(IFERROR((1/D102)*D107,0),"n/a"),"–") -> 0 | M32: =IF(E$85,IFERROR(IFERROR((1/E102)*E107,0),"n/a"),"–") -> 0.0029936263 | N32: =IF(F$85,IFERROR(IFERROR((1/F102)*F107,0),"n/a"),"–") -> 0.00051687033 | O32: =IF(G$85,IFERROR(IFERROR((1/G102)*G107,0),"n/a"),"–") -> 0.0062821327 | R32: =R31+$S$22 -> 0.56 | S32: =IF(S$13,S31*S$18+(S$14+S$15*IF(S$17,$D$71,0))*S$19,NA()) -> 0.0079419526 | T32: =IF(T$13,T31*T$18+(T$14+T$15*IF(T$17,$D$71,(S31+S32)/2))*T$19,NA()) -> 0.077839961 | U32: =IF(U$13,U31*U$18+(U$14+U$15*IF(U$17,$D$71,(T31+T32)/2))*U$19,NA()) -> 0.0099956091 | V32: =IF(V$13,V31*V$18+(V$14+V$15*IF(V$17,$D$71,(U31+U32)/2))*V$19,NA()) -> 5.3571411e-05
B33: 2 ENVIRONMENT | J33: Growth dilution | K33: k2,out (d⁻¹) | L33: =IF(D$85,IFERROR(D86*$L$111*D$50^-0.25,"n/a"),"–") -> 0.10669676 | M33: =IF(E$85,IFERROR(E86*$L$111*E$50^-0.25,"n/a"),"–") -> 0.018973666 | N33: =IF(F$85,IFERROR(F86*$L$111*F$50^-0.25,"n/a"),"–") -> 0.0018973666 | O33: =IF(G$85,IFERROR(G86*$L$111*G$50^-0.25,"n/a"),"–") -> 0.005421612 | R33: =R32+$S$22 -> 0.64 | S33: =IF(S$13,S32*S$18+(S$14+S$15*IF(S$17,$D$71,0))*S$19,NA()) -> 0.0089961379 | T33: =IF(T$13,T32*T$18+(T$14+T$15*IF(T$17,$D$71,(S32+S33)/2))*T$19,NA()) -> 0.085804896 | U33: =IF(U$13,U32*U$18+(U$14+U$15*IF(U$17,$D$71,(T32+T33)/2))*U$19,NA()) -> 0.011393304 | V33: =IF(V$13,V32*V$18+(V$14+V$15*IF(V$17,$D$71,(U32+U33)/2))*V$19,NA()) -> 6.6380451e-05
B34: Parameter | C34: Unit | D34: Value | E34: Notes | J34: Biotransformation | K34: k3,out (d⁻¹) | L34: =IF(D$85,IFERROR(IF(AND($D$56="On",OR(D$46="Fish",D$46="Mammals",D$46="Birds")),LN(2)*(D$50/$L$117)^-0.25/$F$23,0),"n/a"),"–") -> 0 | M34: =IF(E$85,IFERROR(IF(AND($D$56="On",OR(E$46="Fish",E$46="Mammals",E$46="Birds")),LN(2)*(E$50/$L$117)^-0.25/$F$23,0),"n/a"),"–") -> 0 | N34: =IF(F$85,IFERROR(IF(AND($D$56="On",OR(F$46="Fish",F$46="Mammals",F$46="Birds")),LN(2)*(F$50/$L$117)^-0.25/$F$23,0),"n/a"),"–") -> 0 | O34: =IF(G$85,IFERROR(IF(AND($D$56="On",OR(G$46="Fish",G$46="Mammals",G$46="Birds")),LN(2)*(G$50/$L$117)^-0.25/$F$23,0),"n/a"),"–") -> 0 | R34: =R33+$S$22 -> 0.72 | S34: =IF(S$13,S33*S$18+(S$14+S$15*IF(S$17,$D$71,0))*S$19,NA()) -> 0.010031306 | T34: =IF(T$13,T33*T$18+(T$14+T$15*IF(T$17,$D$71,(S33+S34)/2))*T$19,NA()) -> 0.093155915 | U34: =IF(U$13,U33*U$18+(U$14+U$15*IF(U$17,$D$71,(T33+T34)/2))*U$19,NA()) -> 0.012783157 | V34: =IF(V$13,V33*V$18+(V$14+V$15*IF(V$17,$D$71,(U33+U34)/2))*V$19,NA()) -> 7.981834e-05
B35: Water concentration (dissolved) | C35: µg/L | D35: 0.1 | E35: Uptake by aquatic organisms; reference for BAF (water) | J35: Total elimination | K35: Σk_out (d⁻¹) | L35: =IF(D$85,IF(COUNT(L28:L34)=7,SUM(L28:L34),"n/a"),"–") -> 0.22755661 | M35: =IF(E$85,IF(COUNT(M28:M34)=7,SUM(M28:M34),"n/a"),"–") -> 1.0030267 | N35: =IF(F$85,IF(COUNT(N28:N34)=7,SUM(N28:N34),"n/a"),"–") -> 0.08398856 | O35: =IF(G$85,IF(COUNT(O28:O34)=7,SUM(O28:O34),"n/a"),"–") -> 2.4587017 | R35: =R34+$S$22 -> 0.8 | S35: =IF(S$13,S34*S$18+(S$14+S$15*IF(S$17,$D$71,0))*S$19,NA()) -> 0.011047799 | T35: =IF(T$13,T34*T$18+(T$14+T$15*IF(T$17,$D$71,(S34+S35)/2))*T$19,NA()) -> 0.09994035 | U35: =IF(U$13,U34*U$18+(U$14+U$15*IF(U$17,$D$71,(T34+T35)/2))*U$19,NA()) -> 0.014165104 | V35: =IF(V$13,V34*V$18+(V$14+V$15*IF(V$17,$D$71,(U34+U35)/2))*V$19,NA()) -> 9.3756316e-05
B36: Water temperature | C36: K | D36: 288 | E36: Default 288 K | R36: =R35+$S$22 -> 0.88 | S36: =IF(S$13,S35*S$18+(S$14+S$15*IF(S$17,$D$71,0))*S$19,NA()) -> 0.012045956 | T36: =IF(T$13,T35*T$18+(T$14+T$15*IF(T$17,$D$71,(S35+S36)/2))*T$19,NA()) -> 0.10620189 | U36: =IF(U$13,U35*U$18+(U$14+U$15*IF(U$17,$D$71,(T35+T36)/2))*U$19,NA()) -> 0.01553909 | V36: =IF(V$13,V35*V$18+(V$14+V$15*IF(V$17,$D$71,(U35+U36)/2))*V$19,NA()) -> 0.00010808849
B37: Water pH | C37: – | D37: 7 | E37: Default 7 | J37: ="TIME-COURSE – "&$F$15&" (approach to steady state)" -> TIME-COURSE – Metoprolol (approach to steady state) | R37: =R36+$S$22 -> 0.96 | S37: =IF(S$13,S36*S$18+(S$14+S$15*IF(S$17,$D$71,0))*S$19,NA()) -> 0.013026105 | T37: =IF(T$13,T36*T$18+(T$14+T$15*IF(T$17,$D$71,(S36+S37)/2))*T$19,NA()) -> 0.11198084 | U37: =IF(U$13,U36*U$18+(U$14+U$15*IF(U$17,$D$71,(T36+T37)/2))*U$19,NA()) -> 0.016905069 | V37: =IF(V$13,V36*V$18+(V$14+V$15*IF(V$17,$D$71,(U36+U37)/2))*V$19,NA()) -> 0.00012272776
B38: Soil concentration | C38: µg/kg ww | D38: 0 | E38: Detritus diet, pore-water and air uptake; reference for BAF (soil) | R38: =R37+$S$22 -> 1.04 | S38: =IF(S$13,S37*S$18+(S$14+S$15*IF(S$17,$D$71,0))*S$19,NA()) -> 0.013988573 | T38: =IF(T$13,T37*T$18+(T$14+T$15*IF(T$17,$D$71,(S37+S38)/2))*T$19,NA()) -> 0.11731441 | U38: =IF(U$13,U37*U$18+(U$14+U$15*IF(U$17,$D$71,(T37+T38)/2))*U$19,NA()) -> 0.018263002 | V38: =IF(V$13,V37*V$18+(V$14+V$15*IF(V$17,$D$71,(U37+U38)/2))*V$19,NA()) -> 0.0001376025
B39: Soil pH | C39: – | D39: 6.5 | E39: Pore-water speciation | R39: =R38+$S$22 -> 1.12 | S39: =IF(S$13,S38*S$18+(S$14+S$15*IF(S$17,$D$71,0))*S$19,NA()) -> 0.014933679 | T39: =IF(T$13,T38*T$18+(T$14+T$15*IF(T$17,$D$71,(S38+S39)/2))*T$19,NA()) -> 0.12223695 | U39: =IF(U$13,U38*U$18+(U$14+U$15*IF(U$17,$D$71,(T38+T39)/2))*U$19,NA()) -> 0.019612858 | V39: =IF(V$13,V38*V$18+(V$14+V$15*IF(V$17,$D$71,(U38+U39)/2))*V$19,NA()) -> 0.00015265381
B40: Soil organic carbon fraction | C40: – | D40: 0.0405 | E40: Soil partitioning (Armitage & Gobas, 2007) | R40: =R39+$S$22 -> 1.2 | S40: =IF(S$13,S39*S$18+(S$14+S$15*IF(S$17,$D$71,0))*S$19,NA()) -> 0.015861734 | T40: =IF(T$13,T39*T$18+(T$14+T$15*IF(T$17,$D$71,(S39+S40)/2))*T$19,NA()) -> 0.12678013 | U40: =IF(U$13,U39*U$18+(U$14+U$15*IF(U$17,$D$71,(T39+T40)/2))*U$19,NA()) -> 0.020954613 | V40: =IF(V$13,V39*V$18+(V$14+V$15*IF(V$17,$D$71,(U39+U40)/2))*V$19,NA()) -> 0.00016783322
B41: Soil bulk density | C41: kg/L | D41: 1.5 | R41: =R40+$S$22 -> 1.28 | S41: =IF(S$13,S40*S$18+(S$14+S$15*IF(S$17,$D$71,0))*S$19,NA()) -> 0.016773048 | T41: =IF(T$13,T40*T$18+(T$14+T$15*IF(T$17,$D$71,(S40+S41)/2))*T$19,NA()) -> 0.13097321 | U41: =IF(U$13,U40*U$18+(U$14+U$15*IF(U$17,$D$71,(T40+T41)/2))*U$19,NA()) -> 0.022288248 | V41: =IF(V$13,V40*V$18+(V$14+V$15*IF(V$17,$D$71,(U40+U41)/2))*V$19,NA()) -> 0.00018310091
B42: Soil moisture content | C42: – | D42: 0.23 | E42: Fraction | R42: =R41+$S$22 -> 1.36 | S42: =IF(S$13,S41*S$18+(S$14+S$15*IF(S$17,$D$71,0))*S$19,NA()) -> 0.017667922 | T42: =IF(T$13,T41*T$18+(T$14+T$15*IF(T$17,$D$71,(S41+S42)/2))*T$19,NA()) -> 0.13484318 | U42: =IF(U$13,U41*U$18+(U$14+U$15*IF(U$17,$D$71,(T41+T42)/2))*U$19,NA()) -> 0.023613752 | V42: =IF(V$13,V41*V$18+(V$14+V$15*IF(V$17,$D$71,(U41+U42)/2))*V$19,NA()) -> 0.0001984241
R43: =R42+$S$22 -> 1.44 | S43: =IF(S$13,S42*S$18+(S$14+S$15*IF(S$17,$D$71,0))*S$19,NA()) -> 0.018546652 | T43: =IF(T$13,T42*T$18+(T$14+T$15*IF(T$17,$D$71,(S42+S43)/2))*T$19,NA()) -> 0.13841495 | U43: =IF(U$13,U42*U$18+(U$14+U$15*IF(U$17,$D$71,(T42+T43)/2))*U$19,NA()) -> 0.024931118 | V43: =IF(V$13,V42*V$18+(V$14+V$15*IF(V$17,$D$71,(U42+U43)/2))*V$19,NA()) -> 0.00021377586
...

Sheet Chemical Data
A1: Chemical Data – pharmaceuticals available in the Model drop-down
A2: Sorted A–Z. '-' = descriptor not available. To add a compound, fill in a new row directly below the last one: it then appears in the Model drop-down (the list reads column A down to the first empty row).
A3: Identifiers (PubChem) | C3: Ionisation and log Kow (RDKit) | G3: log Koa and pKa (CompTox) | K3: EPI Suite | L3: Abraham descriptors – measured (UFZ-LSERD; averaged) | R3: Abraham descriptors – QSBR estimates
A4: Name | B4: SMILES | C4: Ionising functional group | D4: Ionisation type | E4: log Kow (neutral) | F4: log Kow (ionised) | G4: log Koa | H4: pKa (acidic) | I4: pKa (basic) | J4: pKa (relevant) | K4: Fish half-life (d) | L4: E | M4: S | N4: A | O4: B | P4: V | Q4: L | R4: E | S4: S | T4: A | U4: B | V4: V | W4: L
A5: Acetaminophen | B5: CC(=O)NC1=CC=C(C=C1)O | C5: Phenoxide | D5: Acidic | E5: 1.3506 | F5: 0.7186 | G5: 7.96 | H5: 9.86 | I5: 1.72 | J5: =IF(D5="Acidic",H5,IF(D5="Basic",I5,IF(ABS(H5-7.4)<=ABS(I5-7.4),H5,I5))) -> 9.86 | K5: 0.0108 | L5: 1.09 | M5: 1.66 | N5: 1.0372727 | O5: 0.86363636 | P5: 1.1724 | Q5: 6.44875 | R5: - | S5: - | T5: - | U5: - | V5: - | W5: -
A6: Amitriptyline | B6: CN(C)CCC=C1C2=CC=CC=C2CCC3=CC=CC=C31 | C6: 3° Amine | D6: Basic | E6: 4.1686 | F6: 2.7515 | G6: 9.6 | I6: 9.54 | J6: =IF(D6="Acidic",H6,IF(D6="Basic",I6,IF(ABS(H6-7.4)<=ABS(I6-7.4),H6,I6))) -> 9.54 | K6: 0.598 | L6: 1.9852 | M6: 1.474 | N6: 0 | O6: 1.056 | P6: 2.3996 | Q6: 11.336667 | R6: - | S6: - | T6: - | U6: - | V6: - | W6: -
A7: Aripiprazole | B7: C1CC(=O)NC2=C1C=CC(=C2)OCCCCN3CCN(CC3)C4=C(C(=CC=C4)Cl)Cl | C7: 3° Amine | D7: Basic | E7: 4.8593 | F7: 3.4422 | G7: 10.21 | H7: 11.6 | I7: 7.28 | J7: =IF(D7="Acidic",H7,IF(D7="Basic",I7,IF(ABS(H7-7.4)<=ABS(I7-7.4),H7,I7))) -> 7.28 | K7: 0.134 | L7: - | M7: - | N7: - | O7: - | P7: - | Q7: - | R7: - | S7: - | T7: - | U7: - | V7: - | W7: -
A8: Atenolol | B8: CC(C)NCC(COC1=CC=C(C=C1)CC(=O)N)O | C8: 2° Amine | D8: Basic | E8: 0.4521 | F8: -0.5741 | G8: 9.23 | H8: 13.9 | I8: 8.79 | J8: =IF(D8="Acidic",H8,IF(D8="Basic",I8,IF(ABS(H8-7.4)<=ABS(I8-7.4),H8,I8))) -> 8.79 | K8: 0.014 | L8: 1.45 | M8: 1.89 | N8: 0.634 | O8: 1.962 | P8: 2.1763 | Q8: 10.625 | R8: - | S8: - | T8: - | U8: - | V8: - | W8: -
A9: Azithromycin | B9: CC[C@@H]1[C@@]([C@@H]([C@H](N(C[C@@H](C[C@@]([C@@H]([C@H]([C@@H]([C@H](C(=O)O1)C)O[C@H]2C[C@@]([C@H]([C@@H](O2)C)O)(C)OC)C)O[C@H]3[C@@H]([C@H](C[C@H](O3)C)N(C)C)O)(C)O)C)C)C)O)(C)O | C9: 3° Amine | D9: Basic | E9: 1.9007 | F9: =E9 -> 1.9007 | G9: 9.53 | I9: 8.74 | J9: =IF(D9="Acidic",H9,IF(D9="Basic",I9,IF(ABS(H9-7.4)<=ABS(I9-7.4),H9,I9))) -> 8.74 | K9: 0.02262 | L9: 2.242 | M9: 3.2 | N9: 1.19 | O9: 4.9 | P9: 5.998 | Q9: 22.899 | R9: 1.81 | S9: 2.55 | T9: 1.53 | U9: 5.36 | V9: 5.998 | W9: 22.899
A10: Bezafibrate | B10: CC(C)(C(=O)O)OC1=CC=C(C=C1)CCNC(=O)C2=CC=C(C=C2)Cl | C10: Carboxylic Acid | D10: Acidic | E10: 3.5545 | F10: 2.2198 | G10: 9.46 | H10: 4.25 | I10: -2.06 | J10: =IF(D10="Acidic",H10,IF(D10="Basic",I10,IF(ABS(H10-7.4)<=ABS(I10-7.4),H10,I10))) -> 4.25 | K10: 1.86 | L10: - | M10: - | N10: - | O10: - | P10: - | Q10: - | R10: - | S10: - | T10: - | U10: - | V10: - | W10: -
A11: Caffeine | B11: CN1C=NC2=C1C(=O)N(C(=O)N2C)C | C11: 3° Amine | D11: Basic | E11: -1.0293 | F11: -1.6102 | G11: 8.52 | I11: 1.48 | J11: =IF(D11="Acidic",H11,IF(D11="Basic",I11,IF(ABS(H11-7.4)<=ABS(I11-7.4),H11,I11))) -> 1.48 | K11: 0.0218 | L11: 1.5111333 | M11: 1.7141333 | N11: 0.041666667 | O11: 1.2749333 | P11: 1.3632 | Q11: 7.639 | R11: 1.43 | S11: 1.82 | T11: 0 | U11: 1.27 | V11: 1.3632 | W11: 7.721
A12: Carbamazepine | B12: NC(=O)N1C2=CC=CC=C2C=CC2=CC=CC=C12 | C12: 3° Amine | D12: Neutral | E12: 3.3872 | F12: =E12 -> 3.3872 | G12: 11 | H12: 9.51 | I12: -0.49 | J12: =IF(D12="Acidic",H12,IF(D12="Basic",I12,IF(ABS(H12-7.4)<=ABS(I12-7.4),H12,I12))) -> 9.51 | K12: 0.1499 | L12: 2.1513333 | M12: 1.9383171 | N12: 0.51389429 | O12: 1.0697643 | P12: 1.8106 | Q12: 9.789665 | R12: - | S12: - | T12: - | U12: - | V12: - | W12: -
A13: Celecoxib | B13: CC1=CC=C(C=C1)C2=CC(=NN2C3=CC=C(C=C3)S(=O)(=O)N)C(F)(F)F | C13: 1° Amine | D13: Basic | E13: 3.51392 | F13: 2.93302 | G13: 10.87 | H13: 11.3 | I13: -1.47 | J13: =IF(D13="Acidic",H13,IF(D13="Basic",I13,IF(ABS(H13-7.4)<=ABS(I13-7.4),H13,I13))) -> -1.47 | K13: 6.68 | L13: 2.04 | M13: 2.44 | N13: 0.6 | O13: 1.26 | P13: 2.4675 | Q13: 13.04 | R13: - | S13: - | T13: - | U13: - | V13: - | W13: -
A14: Chloramphenicol | B14: C1=CC(=CC=C1[C@H]([C@@H](CO)NC(=O)C(Cl)Cl)O)[N+](=O)[O-] | C14: 3° Amine | D14: Neutral | E14: 0.909 | F14: =E14 -> 0.909 | G14: 9.24 | H14: 10.4 | I14: -1.73 | J14: =IF(D14="Acidic",H14,IF(D14="Basic",I14,IF(ABS(H14-7.4)<=ABS(I14-7.4),H14,I14))) -> 10.4 | K14: 0.00606 | L14: 1.85 | M14: 1.91 | N14: 0.68 | O14: 1.72 | P14: 2.0728 | Q14: 10.82 | R14: - | S14: - | T14: - | U14: - | V14: - | W14: -
A15: Ciprofloxacin | B15: C1CC1N2C=C(C(=O)C3=CC(=C(C=C32)N4CCNCC4)F)C(=O)O | C15: Carboxylic Acid | D15: Acidic | E15: 1.5833 | F15: 0.2486 | G15: 9.43 | H15: 2.74 | I15: 8.3 | J15: =IF(D15="Acidic",H15,IF(D15="Basic",I15,IF(ABS(H15-7.4)<=ABS(I15-7.4),H15,I15))) -> 2.74 | K15: 0.0203 | L15: - | M15: - | N15: - | O15: - | P15: - | Q15: - | R15: - | S15: - | T15: - | U15: - | V15: - | W15: -
A16: Citalopram | B16: CN(C)CCCC1(C2=C(CO1)C=C(C=C2)C#N)C3=CC=C(C=C3)F | C16: 3° Amine | D16: Basic | E16: 3.81298 | F16: 2.39588 | G16: 10.63 | I16: 8.46 | J16: =IF(D16="Acidic",H16,IF(D16="Basic",I16,IF(ABS(H16-7.4)<=ABS(I16-7.4),H16,I16))) -> 8.46 | K16: 0.691 | L16: 1.83 | M16: 1.99 | N16: 0 | O16: 1.53 | P16: 2.5328 | Q16: 12.14 | R16: - | S16: - | T16: - | U16: - | V16: - | W16: -
A17: Clarithromycin | B17: CC[C@@H]1[C@@]([C@@H]([C@H](C(=O)[C@@H](C[C@@]([C@@H]([C@H]([C@@H]([C@H](C(=O)O1)C)O[C@H]2C[C@@]([C@H]([C@@H](O2)C)O)(C)OC)C)O[C@H]3[C@@H]([C@H](C[C@H](O3)C)N(C)C)O)(C)OC)C)C)O)(C)O | C17: 3° Amine | D17: Basic | E17: 2.4397 | F17: 1.0226 | G17: 9.52 | H17: 13.1 | I17: 7.31 | J17: =IF(D17="Acidic",H17,IF(D17="Basic",I17,IF(ABS(H17-7.4)<=ABS(I17-7.4),H17,I17))) -> 7.31 | K17: 0.0398 | L17: 2.72 | M17: 3.65 | N17: 1 | O17: 4.98 | P17: 5.9139 | Q17: 26.8 | R17: - | S17: - | T17: - | U17: - | V17: - | W17: -
A18: Clozapine | B18: CN1CCN(CC1)C2=NC3=C(C=CC(=C3)Cl)NC4=CC=CC=C42 | C18: 2° Amine | D18: Basic | E18: 3.7227 | F18: 1.8033 | G18: 10.5 | I18: 8.49 | J18: =IF(D18="Acidic",H18,IF(D18="Basic",I18,IF(ABS(H18-7.4)<=ABS(I18-7.4),H18,I18))) -> 8.49 | K18: 0.813 | L18: 2.56 | M18: 1.52 | N18: 0.25 | O18: 1.7 | P18: 2.431 | Q18: 12.38 | R18: - | S18: - | T18: - | U18: - | V18: - | W18: -
A19: Diclofenac | B19: C1=CC=C(C(=C1)CC(=O)O)NC2=C(C=CC=C2Cl)Cl | C19: Carboxylic Acid | D19: Acidic | E19: 4.3641 | F19: 3.0294 | G19: 9.3 | H19: 4.13 | I19: -2.25 | J19: =IF(D19="Acidic",H19,IF(D19="Basic",I19,IF(ABS(H19-7.4)<=ABS(I19-7.4),H19,I19))) -> 4.13 | K19: 6.13 | L19: 1.9657143 | M19: 1.6742857 | N19: 0.60571429 | O19: 0.83857143 | P19: 2.025 | Q19: 11.025 | R19: - | S19: - | T19: - | U19: - | V19: - | W19: -
A20: Diltiazem | B20: CC(=O)O[C@@H]1[C@@H](SC2=CC=CC=C2N(C1=O)CCN(C)C)C3=CC=C(C=C3)OC | C20: 3° Amine | D20: Basic | E20: 3.3685 | F20: 1.9514 | G20: 11.68 | I20: 6.48 | J20: =IF(D20="Acidic",H20,IF(D20="Basic",I20,IF(ABS(H20-7.4)<=ABS(I20-7.4),H20,I20))) -> 6.48 | K20: 0.0236 | L20: 2.6603333 | M20: 2.14 | N20: 0 | O20: 2.22 | P20: 3.1365 | Q20: 15.56 | R20: - | S20: - | T20: - | U20: - | V20: - | W20: -
A21: Diphenhydramine | B21: CN(C)CCOC(C1=CC=CC=C1)C2=CC=CC=C2 | C21: 3° Amine | D21: Basic | E21: 3.3542 | F21: 1.9371 | G21: 8.53 | I21: 8.77 | J21: =IF(D21="Acidic",H21,IF(D21="Basic",I21,IF(ABS(H21-7.4)<=ABS(I21-7.4),H21,I21))) -> 8.77 | K21: 0.0484 | L21: 1.357615 | M21: 1.1947825 | N21: 0 | O21: 1.15111 | P21: 2.1872 | Q21: 9.31 | R21: - | S21: - | T21: - | U21: - | V21: - | W21: -
A22: Doxycycline | B22: C[C@@H]1[C@H]2[C@@H]([C@H]3[C@@H](C(=O)C(=C([C@]3(C(=O)C2=C(C4=C1C=CC=C4O)O)O)O)C(=O)N)N(C)C)O | C22: Phenoxide | D22: Acidic | E22: -0.0824 | F22: -3.3292 | G22: 9.45 | H22: 3.4 | I22: 9.7 | J22: =IF(D22="Acidic",H22,IF(D22="Basic",I22,IF(ABS(H22-7.4)<=ABS(I22-7.4),H22,I22))) -> 3.4 | K22: 1.372e-05 | L22: - | M22: - | N22: - | O22: - | P22: - | Q22: - | R22: 3.45 | S22: 3.35 | T22: 1.89 | U22: 3.52 | V22: 3.0992 | W22: 16.116
A23: Duloxetine | B23: CNCC[C@@H](C1=CC=CS1)OC2=CC=CC3=CC=CC=C32 | C23: 2° Amine | D23: Basic | E23: 4.6309 | F23: 3.6047 | G23: 11.3 | I23: 10 | J23: =IF(D23="Acidic",H23,IF(D23="Basic",I23,IF(ABS(H23-7.4)<=ABS(I23-7.4),H23,I23))) -> 10 | K23: 7.76 | L23: - | M23: - | N23: - | O23: - | P23: - | Q23: - | R23: - | S23: - | T23: - | U23: - | V23: - | W23: -
A24: Enoxacin | B24: CCN1C=C(C(=O)C2=CC(=C(N=C21)N3CCNCC3)F)C(=O)O | C24: Carboxylic Acid | D24: Acidic | E24: 0.6633 | F24: -0.6714 | G24: 9.42 | H24: 3.37 | I24: 6.57 | J24: =IF(D24="Acidic",H24,IF(D24="Basic",I24,IF(ABS(H24-7.4)<=ABS(I24-7.4),H24,I24))) -> 3.37 | K24: 0.00121 | L24: - | M24: - | N24: - | O24: - | P24: - | Q24: - | R24: - | S24: - | T24: - | U24: - | V24: - | W24: -
A25: Enrofloxacin | B25: CCN1CCN(CC1)C2=C(C=C3C(=C2)N(C=C(C3=O)C(=O)O)C4CC4)F | C25: Carboxylic Acid | D25: Acidic | E25: 2.3156 | F25: 0.9809 | G25: 10.38 | H25: 2.68 | I25: 7.65 | J25: =IF(D25="Acidic",H25,IF(D25="Basic",I25,IF(ABS(H25-7.4)<=ABS(I25-7.4),H25,I25))) -> 2.68 | K25: 0.00279 | L25: - | M25: - | N25: - | O25: - | P25: - | Q25: - | R25: - | S25: - | T25: - | U25: - | V25: - | W25: -
A26: Erythromycin | B26: CC[C@@H]1[C@@]([C@@H]([C@H](C(=O)[C@@H](C[C@@]([C@@H]([C@H]([C@@H]([C@H](C(=O)O1)C)O[C@H]2C[C@@]([C@H]([C@@H](O2)C)O)(C)OC)C)O[C@H]3[C@@H]([C@H](C[C@H](O3)C)N(C)C)O)(C)O)C)C)O)(C)O | C26: 3° Amine | D26: Basic | E26: 1.7856 | F26: =E26 -> 1.7856 | G26: 9.53 | H26: 13.1 | I26: 7.14 | J26: =IF(D26="Acidic",H26,IF(D26="Basic",I26,IF(ABS(H26-7.4)<=ABS(I26-7.4),H26,I26))) -> 7.14 | K26: 0.0229 | L26: 2.9 | M26: 3.73 | N26: 1.25 | O26: 4.96 | P26: 5.773 | Q26: 26.13 | R26: - | S26: - | T26: - | U26: - | V26: - | W26: -
A27: Estradiol | B27: C[C@]12CC[C@H]3[C@H]([C@@H]1CC[C@@H]2O)CCC4=C3C=CC(=C4)O | C27: Phenoxide | D27: Acidic | E27: 3.6092 | F27: 2.9772 | G27: 9.15 | H27: 11 | J27: =IF(D27="Acidic",H27,IF(D27="Basic",I27,IF(ABS(H27-7.4)<=ABS(I27-7.4),H27,I27))) -> 11 | K27: 0.0834 | L27: 1.8 | M27: 1.96125 | N27: 0.8625 | O27: 1.08125 | P27: 2.1988 | Q27: 11.09131 | R27: - | S27: - | T27: - | U27: - | V27: - | W27: -
A28: Flumequine | B28: CC1CCC2=C3N1C=C(C(=O)C3=CC(=C2)F)C(=O)O | C28: Carboxylic Acid | D28: Acidic | E28: 2.346 | F28: 1.0113 | G28: 10.62 | H28: 2.54 | I28: -1.98 | J28: =IF(D28="Acidic",H28,IF(D28="Basic",I28,IF(ABS(H28-7.4)<=ABS(I28-7.4),H28,I28))) -> 2.54 | K28: 0.075 | L28: - | M28: - | N28: - | O28: - | P28: - | Q28: - | R28: - | S28: - | T28: - | U28: - | V28: - | W28: -
A29: Fluoxetine | B29: CNCCC(OC1=CC=C(C=C1)C(F)(F)F)C1=CC=CC=C1 | C29: 2° Amine | D29: Basic | E29: 4.435 | F29: 3.4088 | G29: 9.79 | I29: 11.3 | J29: =IF(D29="Acidic",H29,IF(D29="Basic",I29,IF(ABS(H29-7.4)<=ABS(I29-7.4),H29,I29))) -> 11.3 | K29: 3.11 | L29: 1.092 | M29: 1.3 | N29: 0.108 | O29: 0.97 | P29: 2.2403 | Q29: 9.968 | R29: - | S29: - | T29: - | U29: - | V29: - | W29: -
A30: Fluvoxamine | B30: COCCCC/C(=N\OCCN)/C1=CC=C(C=C1)C(F)(F)F | C30: 1° Amine | D30: Basic | E30: 3.2015 | F30: 2.4847 | G30: 9.3 | I30: 7.05 | J30: =IF(D30="Acidic",H30,IF(D30="Basic",I30,IF(ABS(H30-7.4)<=ABS(I30-7.4),H30,I30))) -> 7.05 | K30: 4.42 | L30: 0.78 | M30: 1.1 | N30: 0.16 | O30: 1.36 | P30: 2.3116 | Q30: 9.26 | R30: - | S30: - | T30: - | U30: - | V30: - | W30: -
A31: Hydroxyzine | B31: C1CN(CCN1CCOCCO)C(C2=CC=CC=C2)C3=CC=C(C=C3)Cl | C31: 3° Amine | D31: Basic | E31: 3.0559 | F31: 1.6388 | G31: 10.41 | H31: 14.4 | I31: 6.61 | J31: =IF(D31="Acidic",H31,IF(D31="Basic",I31,IF(ABS(H31-7.4)<=ABS(I31-7.4),H31,I31))) -> 6.61 | K31: 0.00817 | L31: 2 | M31: 2.185 | N31: 0.1 | O31: 1.885 | P31: 2.9231 | Q31: 13.88 | R31: - | S31: - | T31: - | U31: - | V31: - | W31: -
A32: Ibuprofen | B32: CC(C)CC1=CC=C(C=C1)C(C)C(=O)O | C32: Carboxylic Acid | D32: Acidic | E32: 3.0732 | F32: 1.7385 | G32: 8.76 | H32: 4.66 | J32: =IF(D32="Acidic",H32,IF(D32="Basic",I32,IF(ABS(H32-7.4)<=ABS(I32-7.4),H32,I32))) -> 4.66 | K32: 1.87 | L32: 0.72625 | M32: 0.69875 | N32: 0.575 | O32: 0.77125 | P32: 1.7771 | Q32: 7.126932 | R32: - | S32: - | T32: - | U32: - | V32: - | W32: -
A33: Ketoconazole | B33: CC(=O)N1CCN(CC1)C2=CC=C(C=C2)OC[C@@H]3CO[C@@](O3)(CN4C=CN=C4)C5=C(C=C(C=C5)Cl)Cl | C33: 3° Amine | D33: Basic | E33: 4.2058 | F33: 2.7887 | G33: 11.68 | H33: 7.97 | I33: 6.73 | J33: =IF(D33="Acidic",H33,IF(D33="Basic",I33,IF(ABS(H33-7.4)<=ABS(I33-7.4),H33,I33))) -> 6.73 | K33: 0.984 | L33: 3.14 | M33: 3.68 | N33: 0 | O33: 2.6 | P33: 3.7208 | Q33: 19.71 | R33: - | S33: - | T33: - | U33: - | V33: - | W33: -
A34: Ketoprofen | B34: CC(C1=CC(=CC=C1)C(=O)C2=CC=CC=C2)C(=O)O | C34: Carboxylic Acid | D34: Acidic | E34: 3.1057 | F34: 1.771 | G34: 10.57 | H34: 4.19 | J34: =IF(D34="Acidic",H34,IF(D34="Basic",I34,IF(ABS(H34-7.4)<=ABS(I34-7.4),H34,I34))) -> 4.19 | K34: 0.74 | L34: 1.634 | M34: 2.0888 | N34: 0.5492 | O34: 0.8876 | P34: 1.9779 | Q34: 10.527 | R34: - | S34: - | T34: - | U34: - | V34: - | W34: -
A35: Lomefloxacin | B35: CCN1C=C(C(=O)C2=CC(=C(C(=C21)F)N3CCNC(C3)C)F)C(=O)O | C35: Carboxylic Acid | D35: Acidic | E35: 1.7959 | F35: 0.4612 | G35: 9.28 | H35: 3.01 | I35: 7.64 | J35: =IF(D35="Acidic",H35,IF(D35="Basic",I35,IF(ABS(H35-7.4)<=ABS(I35-7.4),H35,I35))) -> 3.01 | K35: 0.02058 | L35: - | M35: - | N35: - | O35: - | P35: - | Q35: - | R35: 2.07 | S35: 2.48 | T35: 0.53 | U35: 1.89 | V35: 2.431 | W35: 11.851
A36: Metoprolol | B36: CC(C)NCC(COC1=CC=C(C=C1)CCOC)O | C36: 2° Amine | D36: Basic | E36: 1.6132 | F36: 0.587 | G36: 8.4 | H36: 13.9 | I36: 9.93 | J36: =IF(D36="Acidic",H36,IF(D36="Basic",I36,IF(ABS(H36-7.4)<=ABS(I36-7.4),H36,I36))) -> 9.93 | K36: 0.325 | L36: 1.162 | M36: 1.3 | N36: 0.156 | O36: 1.696 | P36: 2.2604 | Q36: 9.83 | R36: - | S36: - | T36: - | U36: - | V36: - | W36: -
A37: Naproxen | B37: C[C@@H](C1=CC2=C(C=C1)C=C(C=C2)OC)C(=O)O | C37: Carboxylic Acid | D37: Acidic | E37: 3.0365 | F37: 1.7018 | G37: 9.75 | H37: 4.7 | J37: =IF(D37="Acidic",H37,IF(D37="Basic",I37,IF(ABS(H37-7.4)<=ABS(I37-7.4),H37,I37))) -> 4.7 | K37: 1.74 | L37: 1.51 | M37: 2.0003333 | N37: 0.6 | O37: 0.6755 | P37: 1.7821 | Q37: 9.207 | R37: - | S37: - | T37: - | U37: - | V37: - | W37: -
A38: Norfloxacin | B38: CCN1C=C(C(=O)C2=CC(=C(C=C21)N3CCNCC3)F)C(=O)O | C38: Carboxylic Acid | D38: Acidic | E38: 1.2683 | F38: -0.0664 | G38: 9.38 | H38: 2.23 | I38: 8.69 | J38: =IF(D38="Acidic",H38,IF(D38="Basic",I38,IF(ABS(H38-7.4)<=ABS(I38-7.4),H38,I38))) -> 2.23 | K38: 0.01 | L38: - | M38: - | N38: - | O38: - | P38: - | Q38: - | R38: - | S38: - | T38: - | U38: - | V38: - | W38: -
A39: Ofloxacin | B39: CC1COC2=C3N1C=C(C(=O)C3=CC(=C2N4CCN(CC4)C)F)C(=O)O | C39: Carboxylic Acid | D39: Acidic | E39: 1.544 | F39: 0.2093 | G39: 10.42 | H39: 3.59 | I39: 7.38 | J39: =IF(D39="Acidic",H39,IF(D39="Basic",I39,IF(ABS(H39-7.4)<=ABS(I39-7.4),H39,I39))) -> 3.59 | K39: 0.000782 | L39: - | M39: - | N39: - | O39: - | P39: - | Q39: - | R39: - | S39: - | T39: - | U39: - | V39: - | W39: -
A40: Orlistat | B40: CCCCCCCCCCC[C@@H](C[C@H]1[C@@H](C(=O)O1)CCCCCC)OC(=O)[C@H](CC(C)C)NC=O | C40: None | D40: Neutral | E40: 6.8819 | F40: =E40 -> 6.8819 | G40: 10.2 | H40: 2.66 | I40: 12.7 | J40: =IF(D40="Acidic",H40,IF(D40="Basic",I40,IF(ABS(H40-7.4)<=ABS(I40-7.4),H40,I40))) -> 2.66 | K40: 0.032 | L40: - | M40: - | N40: - | O40: - | P40: - | Q40: - | R40: 0.36 | S40: 1.32 | T40: 0.27 | U40: 1.61 | V40: 4.3504 | W40: 15.795
...
