Workbook

Sheet Input and Output
A1: Input Parameters
A2: Chemical Data (Manual) | C2: Species Data
A3: Name | B3: Sertraline | C3: Trohic Level | D3: 1 | E3: 2 | F3: 3 | G3: 4
A4: logKow | B4: 5.1796 | C4: Species | D4: Plants | E4: Crustaceans | F4: Fish | G4: None
A5: Ionic logKow | B5: 4.1534 | C5: Mass (kg) | D5: 0.15 | E5: 0.76 | F5: 0.5 | G5: 1.5
A6: logkoa | B6: 5.1796 | C6: Enivronment | D6: Aquatic | E6: Aquatic | F6: Aquatic | G6: Aquatic
A7: pka | B7: 8.16 | C7: Diet | D7: Photosynthesis | E7: Herbivore | F7: Carnivore | G7: Carnivore
A8: Environmental Data | C8: Blood Type | D8: Cold Blooded | E8: Cold Blooded | F8: Cold Blooded | G8: Cold Blooded
A9: Aquatic | C9: pH (organism) | D9: 7.7 | E9: 7.7 | F9: 7.7 | G9: 7.7
A10: Concentration (ug/L) | B10: 15 | C10: LFER Estimations | E10: Biodegredation
A11: Temperature (K) | B11: 293 | C11: Submodel | D11: On | E11: Submodel | F11: On
A12: pH | B12: 7.9 | C12: Ionisation Type | D12: Basic | E12: Half-Life | F12: 45.8
A13: Terrestrial (Soil) | C13: Functional Group | D13: 2° Amine | E13: Timescale
A14: Concentration (ug/kg) | B14: 0 | C14: E | D14: 1.83 | E14: Timestep | F14: Hours
A15: Temperature (K) | B15: 288 | C15: S | D15: 1.5 | E15: Modifier | F15: 1
A16: pH | B16: 6.5 | C16: A | D16: 0.1 | E16: Useful Links
A17: OC Fraction | B17: 0.0405 | C17: B | D17: 0.82 | E17: Instructions | F17: https://github.com/FunkNoodle/Secondary-Poisoning-Model
A18: Density (kg/m^3) | B18: 1500 | C18: V | D18: 2.2647 | E18: LFER Parameters | F18: http://www.ufz.de/lserd
A19: Soil moisture Content | B19: 0.23 | C19: L | D19: 10.84 | E19: Half-Life | F19: https://episuite.dev/
A21: Kinetic Constants
A22: Symbol | B22: =_xlfn.CONCAT("TL ",D3,"-",D4) -> TL 1-Plants | C22: =_xlfn.CONCAT("TL ",E3,"-",E4) -> TL 2-Crustaceans | D22: =_xlfn.CONCAT("TL ",F3,"-",F4) -> TL 3-Fish | E22: =_xlfn.CONCAT("TL ",G3,"-",G4) -> TL 4-None | F22: Descrption
A23: k0_in-aq | B23: =IF(D4="None",0,IF(OR(D6="Aquatic",D6="Subterranean"),((D5)^-0.25)/(Calculations!C19+(Calculations!C20/Calculations!C17)+(1/Calculations!C23)),0)) -> 20.855766 | C23: =IF(E4="None",0,IF(OR(E6="Aquatic",E6="Subterranean"),((E5)^-0.25)/(Calculations!D19+(Calculations!D20/Calculations!D17)+(1/Calculations!D23)),0)) -> 218.61429 | D23: =IF(F4="None",0,IF(OR(F6="Aquatic",F6="Subterranean"),((F5)^-0.25)/(Calculations!E19+(Calculations!E20/Calculations!E17)+(1/Calculations!E23)),0)) -> 242.73893 | E23: =IF(G4="None",0,IF(OR(G6="Aquatic",G6="Subterranean"),((G5)^-0.25)/(Calculations!F19+(Calculations!F20/Calculations!F17)+(1/Calculations!F23)),0)) -> 0 | F23: Water absorption uptake
A24: k0_in-air | B24: =IF(D4="None",0,IF(D6="Terrestrial",((D5)^-0.25)/(Calculations!J15+(Calculations!J18/Calculations!J16)+(1/Calculations!J21)),0)) -> 0 | C24: =IF(E4="None",0,IF(E6="Terrestrial",((E5)^-0.25)/(Calculations!K15+(Calculations!K18/Calculations!K16)+(1/Calculations!K21)),0)) -> 0 | D24: =IF(F4="None",0,IF(F6="Terrestrial",((F5)^-0.25)/(Calculations!L15+(Calculations!L18/Calculations!L16)+(1/Calculations!L21)),0)) -> 0 | E24: =IF(G4="None",0,IF(G6="Terrestrial",((G5)^-0.25)/(Calculations!M15+(Calculations!M18/Calculations!M16)+(1/Calculations!M21)),0)) -> 0 | F24: Air absorption uptake
A25: k0_in-pw | B25: =IF(D4="None",0,IF(D6="Subterranean",((D5)^-0.25)/(Calculations!C19+(Calculations!C20/Calculations!C17)),0)) -> 0 | C25: =IF(E4="None",0,IF(E6="Subterranean",((E5)^-0.25)/(Calculations!D19+(Calculations!D20/Calculations!D17)),0)) -> 0 | D25: =IF(F4="None",0,IF(F6="Subterranean",((F5)^-0.25)/(Calculations!E19+(Calculations!E20/Calculations!E17)),0)) -> 0 | E25: =IF(G4="None",0,IF(G6="Subterranean",((G5)^-0.25)/(Calculations!F19+(Calculations!F20/Calculations!F17)),0)) -> 0 | F25: Pore-water absorption
A26: k1_in | B26: =IF(D4="None",0,IFERROR(IF(D7="Detritus",(Calculations!C24/(1-Calculations!C24))*(1/Calculations!$C$3)*(((D5)^-0.25)/(Calculations!$C$25+(Calculations!C20/(Calculations!C13*Calculations!C17))+(1/(Calculations!C30*Calculations!C17*(1-Calculations!C24)*Calculations!C32)))),(Calculations!C24/(1-Calculations!C24))*(1/(IF($D11="Off",Calculations!B42,Calculations!B43)))*(((D5)^-0.25)/(Calculations!$C$25+(Calculations!C20/(Calculations!C13*Calculations!C17))+(1/(Calculations!C30*Calculations!C17*(1-Calculations!C24)*Calculations!C32))))),0)) -> 0 | C26: =IF(E4="None",0,IFERROR(IF(E7="Detritus",(Calculations!D24/(1-Calculations!D24))*(1/Calculations!$C$3)*(((E5)^-0.25)/(Calculations!$C$25+(Calculations!D20/(Calculations!D13*Calculations!D17))+(1/(Calculations!D30*Calculations!D17*(1-Calculations!D24)*Calculations!D32)))),(Calculations!D24/(1-Calculations!D24))*(1/(IF($D11="Off",Calculations!C42,Calculations!C43)))*(((E5)^-0.25)/(Calculations!$C$25+(Calculations!D20/(Calculations!D13*Calculations!D17))+(1/(Calculations!D30*Calculations!D17*(1-Calculations!D24)*Calculations!D32))))),0)) -> 0.020618055 | D26: =IF(F4="None",0,IFERROR(IF(F7="Detritus",(Calculations!E24/(1-Calculations!E24))*(1/Calculations!$C$3)*(((F5)^-0.25)/(Calculations!$C$25+(Calculations!E20/(Calculations!E13*Calculations!E17))+(1/(Calculations!E30*Calculations!E17*(1-Calculations!E24)*Calculations!E32)))),(Calculations!E24/(1-Calculations!E24))*(1/(IF($D11="Off",Calculations!D42,Calculations!D43)))*(((F5)^-0.25)/(Calculations!$C$25+(Calculations!E20/(Calculations!E13*Calculations!E17))+(1/(Calculations!E30*Calculations!E17*(1-Calculations!E24)*Calculations!E32))))),0)) -> 0.024827144 | E26: =IF(G4="None",0,IFERROR(IF(G7="Detritus",(Calculations!F24/(1-Calculations!F24))*(1/Calculations!$C$3)*(((G5)^-0.25)/(Calculations!$C$25+(Calculations!F20/(Calculations!F13*Calculations!F17))+(1/(Calculations!F30*Calculations!F17*(1-Calculations!F24)*Calculations!F32)))),(Calculations!F24/(1-Calculations!F24))*(1/(IF($D11="Off",Calculations!E42,Calculations!E43)))*(((G5)^-0.25)/(Calculations!$C$25+(Calculations!F20/(Calculations!F13*Calculations!F17))+(1/(Calculations!F30*Calculations!F17*(1-Calculations!F24)*Calculations!F32))))),0)) -> 0 | F26: Assimilation uptake from food
A27: k0_out-aq | B27: =IF(D4="None",0,IF(D6="aquatic",(1/(IF($D11="Off",Calculations!C42,Calculations!C43)))*B26,0)) -> 0 | C27: =IF(E4="None",0,IF(E6="aquatic",(1/(IF($D11="Off",Calculations!D42,Calculations!D43)))*C26,0)) -> 1.8390864e-05 | D27: =IF(F4="None",0,IF(F6="aquatic",(1/(IF($D11="Off",Calculations!E42,Calculations!E43)))*D26,0)) -> 1.1657538e-05 | E27: =IF(G4="None",0,IF(G6="aquatic",(1/(IF($D11="Off",Calculations!F42,Calculations!F43)))*E26,0)) -> 0 | F27: Expiration to Water
A28: k0_out-air | B28: =IF(D4="None",0,IF(D6="Terrestrial",(1/Calculations!J16)*B24,0)) -> 0 | C28: =IF(E4="None",0,IF(E6="Terrestrial",(1/Calculations!K16)*C24,0)) -> 0 | D28: =IF(F4="None",0,IF(F6="Terrestrial",(1/Calculations!L16)*D24,0)) -> 0 | E28: =IF(G4="None",0,IF(G6="Terrestrial",(1/Calculations!M16)*E24,0)) -> 0 | F28: Expiration to air
A29: K1_out_urine | B29: {=IF(D4="None",0,IFERROR(_xlfn.IFS(D6="Terrestrial",(Calculations!J22*Calculations!J27*(1-Calculations!J32))/Calculations!J28,D6="Subterranean",(Calculations!J22*Calculations!J27*(1-Calculations!J32))/Calculations!J28),0))} -> 0 | C29: {=IF(E4="None",0,IFERROR(_xlfn.IFS(E6="Terrestrial",(Calculations!K22*Calculations!K27*(1-Calculations!K32))/Calculations!K28,E6="Subterranean",(Calculations!K22*Calculations!K27*(1-Calculations!K32))/Calculations!K28),0))} -> 0 | D29: {=IF(F4="None",0,IFERROR(_xlfn.IFS(F6="Terrestrial",(Calculations!L22*Calculations!L27*(1-Calculations!L32))/Calculations!L28,F6="Subterranean",(Calculations!L22*Calculations!L27*(1-Calculations!L32))/Calculations!L28),0))} -> 0 | E29: {=IF(G4="None",0,IFERROR(_xlfn.IFS(G6="Terrestrial",(Calculations!M22*Calculations!M27*(1-Calculations!M32))/Calculations!M28,G6="Subterranean",(Calculations!M22*Calculations!M27*(1-Calculations!M32))/Calculations!M28),0))} -> 0 | F29: Excretion to Urine
A30: k1_out | B30: =IF(D4="None",0,IFERROR((1/(IF(D11="Off",Calculations!C42,Calculations!C43)))*(((D5)^-0.25)/(Calculations!$C$25+(Calculations!C20/(Calculations!C13*Calculations!C17))+(1/(Calculations!C30*Calculations!C17*(1-Calculations!C24)*Calculations!C32)))),0)) -> 0 | C30: =IF(E4="None",0,IFERROR((1/(IF(E11="Off",Calculations!D42,Calculations!D43)))*(((E5)^-0.25)/(Calculations!$C$25+(Calculations!D20/(Calculations!D13*Calculations!D17))+(1/(Calculations!D30*Calculations!D17*(1-Calculations!D24)*Calculations!D32)))),0)) -> 0.0026921207 | D30: =IF(F4="None",0,IFERROR((1/(IF(F11="Off",Calculations!E42,Calculations!E43)))*(((F5)^-0.25)/(Calculations!$C$25+(Calculations!E20/(Calculations!E13*Calculations!E17))+(1/(Calculations!E30*Calculations!E17*(1-Calculations!E24)*Calculations!E32)))),0)) -> 0.0032673255 | E30: =IF(G4="None",0,IFERROR((1/(IF(G11="Off",Calculations!F42,Calculations!F43)))*(((G5)^-0.25)/(Calculations!$C$25+(Calculations!F20/(Calculations!F13*Calculations!F17))+(1/(Calculations!F30*Calculations!F17*(1-Calculations!F24)*Calculations!F32)))),0)) -> 0 | F30: Egestion with Faeces
A31: k2_out | B31: =IF(D4="None",0,Calculations!C13*Calculations!$C$33*(D5)^-0.25) -> 0.0009641141 | C31: =IF(E4="None",0,Calculations!D13*Calculations!$C$33*(E5)^-0.25) -> 0.00064261055 | D31: =IF(F4="None",0,Calculations!E13*Calculations!$C$33*(F5)^-0.25) -> 0.00071352427 | E31: =IF(G4="None",0,Calculations!F13*Calculations!$C$33*(G5)^-0.25) -> 0 | F31: Dilution by biomass
A32: k3_out | B32: =IF(D4="None",0,IF($F11="On",IF(OR(D4="Fish",D4="Mammals",D4="Birds"),((LN(2)*((D5)/70)^-0.25)/$F$12),0),0)) -> 0 | C32: =IF(E4="None",0,IF($F11="On",IF(OR(E4="Fish",E4="Mammals",E4="Birds"),((LN(2)*((E5)/70)^-0.25)/$F$12),0),0)) -> 0 | D32: =IF(F4="None",0,IF($F11="On",IF(OR(F4="Fish",F4="Mammals",F4="Birds"),((LN(2)*((F5)/70)^-0.25)/$F$12),0),0)) -> 0.052058541 | E32: =IF(G4="None",0,IF($F11="On",IF(OR(G4="Fish",G4="Mammals",G4="Birds"),((LN(2)*((G5)/70)^-0.25)/$F$12),0),0)) -> 0 | F32: Biotransformation
A34: Output Parameters
A35: =B3 -> Sertraline | B35: =D4 -> Plants | C35: =E4 -> Crustaceans | D35: =F4 -> Fish | E35: =G4 -> None
A36: Steady-State Conc. (ug/kg wet weight) | B36: =IFERROR(MAX('Kinetic Model'!H3:H1048576), "-") -> 324480.78 | C36: =IFERROR(MAX('Kinetic Model'!I3:I1048576), "-") -> 2973162.4 | D36: =IFERROR(MAX('Kinetic Model'!J3:J1048576), "-") -> 1381887.4 | E36: =IFERROR(MAX('Kinetic Model'!K3:K1048576), "-") -> -
A37: BCF/BAF | B37: =IFERROR(B36/$B$10,"-") -> 21632.052 | C37: =IFERROR(C36/$B$10,"-") -> 198210.83 | D37: =IFERROR(D36/$B$10,"-") -> 92125.824 | E37: =IFERROR(E36/$B$10,"-") -> -
A38: BMF | B38: =IFERROR(B36/A36,"-") -> - | C38: =IFERROR(C36/B36,"-") -> 9.1628307 | D38: =IFERROR(D36/C36,"-") -> 0.46478704 | E38: =IFERROR(E36/D36,"-") -> -

Sheet Calculations
A1: Soil/ Water/Air Coefficients | E1: LFER Calculations
A2: Air:Soil Partition Coefficient | B2: K_AS | C2: =1/('Input and Output'!B18*'Input and Output'!B17*2*10^'Input and Output'!B6) -> 5.4428169e-08 | E2: LFER Ionised Coefficient | F2: Current Selection | G2: Carboxylic Acid | H2: Phenoxide | I2: 1° Amine | J2: 2° Amine | K2: 3° Amine
A3: Soil:Water Partition Coefficient | B3: K_SW | C3: ='Input and Output'!B18*'Input and Output'!B17*2*Calculations!C17 -> 7632162.7 | E3: Ei | F3: =IF('Input and Output'!$D$13="None",'Input and Output'!D14,HLOOKUP('Input and Output'!$D$13,$G$2:$K$9,2,FALSE)) -> 1.68 | G3: =0.15+1*'Input and Output'!D14 -> 1.98 | H3: =0.15+1*'Input and Output'!D14 -> 1.98 | I3: =-0.15+1*'Input and Output'!D14 -> 1.68 | J3: =-0.15+1*'Input and Output'!D14 -> 1.68 | K3: =-0.15+1*'Input and Output'!D14 -> 1.68
A4: Concentration in Soil (ug/L) | B4: C_S | C4: =IFERROR(('Input and Output'!B14*'Input and Output'!B18)/1000,0) -> 0 | E4: Si | F4: =IF('Input and Output'!$D$13="None",'Input and Output'!D15,HLOOKUP('Input and Output'!$D$13,$G$2:$K$9,3,FALSE)) -> 3.15608 | G4: =1.224+0.908*'Input and Output'!D14+0.827*'Input and Output'!D15+0.453*'Input and Output'!D18 -> 5.1520491 | H4: =4.692+4.639*'Input and Output'!D14-2.9*'Input and Output'!D15+5.326*'Input and Output'!D16+5.218*'Input and Output'!D17-0.776*'Input and Output'!B7 -> 7.31057 | I4: =0.463+0.473*'Input and Output'!D16+2.419*'Input and Output'!D18 -> 5.9886093 | J4: =0.463+0.473*'Input and Output'!D15+2.419*'Input and Output'!D17 -> 3.15608 | K4: =0.463+0.473*'Input and Output'!D15+2.419*'Input and Output'!D17 -> 3.15608
A5: Concentration in Air (ug/L) | B5: C_A | C5: =IFERROR(C4*C2,0) -> 0 | E5: Ai | F5: =IF('Input and Output'!$D$13="None",'Input and Output'!D16,HLOOKUP('Input and Output'!$D$13,$G$2:$K$9,4,FALSE)) -> 2.1815 | G5: =-0.208-0.058*'Input and Output'!D15+0.354*'Input and Output'!D16+0.076*'Input and Output'!D18 -> -0.0874828 | H5: 0 | I5: =-0.052-0.35*'Input and Output'!D14+1.48*'Input and Output'!D15+0.327*3 -> 2.5085 | J5: =-0.052-0.35*'Input and Output'!D14+1.48*'Input and Output'!D15+0.327*2 -> 2.1815 | K5: =-0.052-0.35*'Input and Output'!D14+1.48*'Input and Output'!D15+0.327 -> 1.8545
A6: Concentration in Pore Water (ug/L) | B6: C_W | C6: =IFERROR(C4/C3,0) -> 0 | E6: Bi | F6: =IF('Input and Output'!$D$13="None",'Input and Output'!D17,HLOOKUP('Input and Output'!$D$13,$G$2:$K$9,5,FALSE)) -> 0 | G6: =2.15-0.204*'Input and Output'!D15+1.217*'Input and Output'!D17+0.314*'Input and Output'!D18 -> 3.5530558 | H6: =1.7+1.103*'Input and Output'!D14-0.732*'Input and Output'!D15+0.728*'Input and Output'!D16+0.564*'Input and Output'!D17-0.0255*'Input and Output'!B7 -> 2.94769 | I6: 0 | J6: 0 | K6: 0
E7: Vi | F7: =IF('Input and Output'!$D$13="None",'Input and Output'!D18,HLOOKUP('Input and Output'!$D$13,$G$2:$K$9,6,FALSE)) -> 2.2862 | G7: =-0.0215+1*'Input and Output'!D18 -> 2.2432 | H7: =-0.0215+1*'Input and Output'!D18 -> 2.2432 | I7: =0.0215+1*'Input and Output'!D18 -> 2.2862 | J7: =0.0215+1*'Input and Output'!D18 -> 2.2862 | K7: =0.0215+1*'Input and Output'!D18 -> 2.2862
E8: Ji_pos | F8: =IF('Input and Output'!$D$13="None",0,HLOOKUP('Input and Output'!$D$13,$G$2:$K$9,7,FALSE)) -> 1.81362 | G8: 0 | H8: 0 | I8: =0.628+1.002*'Input and Output'!D14-0.794*'Input and Output'!D15+1.128*'Input and Output'!D17-0.191*3 -> 1.62262 | J8: =0.628+1.002*'Input and Output'!D14-0.794*'Input and Output'!D15+1.128*'Input and Output'!D17-0.191*2 -> 1.81362 | K8: =0.628+1.002*'Input and Output'!D14-0.794*'Input and Output'!D15+1.128*'Input and Output'!D17-0.191 -> 2.00462
E9: Ji_neg | F9: =IF('Input and Output'!$D$13="None",0,HLOOKUP('Input and Output'!$D$13,$G$2:$K$9,8,FALSE)) -> 0 | G9: =1.793+ 0.267*'Input and Output'!D14-0.195*'Input and Output'!D15+0.35*'Input and Output'!D18 -> 2.781755 | H9: =2.165+2.579*'Input and Output'!D14-1.504*'Input and Output'!D15+1.708*'Input and Output'!D16+0.045*'Input and Output'!D17-0.217*'Input and Output'!B7 -> 3.06555 | I9: 0 | J9: 0 | K9: 0
A11: Aquatic | H11: Terrestrial
A12: Parameter | B12: Symbol | C12: =_xlfn.CONCAT("TL ",'Input and Output'!D3,"-",'Input and Output'!D4) -> TL 1-Plants | D12: =_xlfn.CONCAT("TL ",'Input and Output'!E3,"-",'Input and Output'!E4) -> TL 2-Crustaceans | E12: =_xlfn.CONCAT("TL ",'Input and Output'!F3,"-",'Input and Output'!F4) -> TL 3-Fish | F12: =_xlfn.CONCAT("TL ",'Input and Output'!G3,"-",'Input and Output'!G4) -> TL 4-None | H12: Parameter | I12: Symbol | J12: =_xlfn.CONCAT("TL ",'Input and Output'!D3,"-",'Input and Output'!D4) -> TL 1-Plants | K12: =_xlfn.CONCAT("TL ",'Input and Output'!E3,"-",'Input and Output'!E4) -> TL 2-Crustaceans | L12: =_xlfn.CONCAT("TL ",'Input and Output'!F3,"-",'Input and Output'!F4) -> TL 3-Fish | M12: =_xlfn.CONCAT("TL ",'Input and Output'!G3,"-",'Input and Output'!G4) -> TL 4-None
A13: Temperature correction factor | B13: qT | C13: =IF('Input and Output'!D8="Warm Blooded", 10,1) -> 1 | D13: =IF('Input and Output'!E8="Warm Blooded", 10,1) -> 1 | E13: =IF('Input and Output'!F8="Warm Blooded", 10,1) -> 1 | F13: =IF('Input and Output'!G8="Warm Blooded", 10,1) -> 1 | H13: Ventilation (L/day) | I13: Ve | J13: {=IFERROR(_xlfn.IFS('Input and Output'!D4="Birds",554.4,'Input and Output'!D4="Mammals",745.92,'Input and Output'!D4="Insects",180)*'Input and Output'!D5^0.75,"-")} -> - | K13: {=IFERROR(_xlfn.IFS('Input and Output'!E4="Birds",554.4,'Input and Output'!E4="Mammals",745.92,'Input and Output'!E4="Insects",180)*'Input and Output'!E5^0.75,"-")} -> - | L13: {=IFERROR(_xlfn.IFS('Input and Output'!F4="Birds",554.4,'Input and Output'!F4="Mammals",745.92,'Input and Output'!F4="Insects",180)*'Input and Output'!F5^0.75,"-")} -> - | M13: {=IFERROR(_xlfn.IFS('Input and Output'!G4="Birds",554.4,'Input and Output'!G4="Mammals",745.92,'Input and Output'!G4="Insects",180)*'Input and Output'!G5^0.75,"-")} -> -
A14: Production efficiency | B14: p_p | C14: {=_xlfn.IFS('Input and Output'!D4="Algae",0.5,'Input and Output'!D4="Plants",0.5, 'Input and Output'!D4="Molluscs",0.25,'Input and Output'!D4="Worms",0.25, 'Input and Output'!D4="Arthropods", 0.25,'Input and Output'!D4="Crustaceans", 0.25,'Input and Output'!D4="Insects", 0.25,AND('Input and Output'!D4="Fish",'Input and Output'!D8="Cold Blooded"),0.1,AND('Input and Output'!D4="Fish",'Input and Output'!D8="Warm Blooded"),'Input and Output'!D4="Amphibians",0.1,0.02,'Input and Output'!D4="Birds",0.02,'Input and Output'!D4="Mammals",0.02,'Input and Output'!D4="Cnidaria",0.35)} -> 0.5 | D14: {=_xlfn.IFS('Input and Output'!E4="Algae",0.5,'Input and Output'!E4="Plants",0.5, 'Input and Output'!E4="Molluscs",0.25,'Input and Output'!E4="Worms",0.25, 'Input and Output'!E4="Arthropods", 0.25,'Input and Output'!E4="Crustaceans", 0.25,'Input and Output'!E4="Insects", 0.25,AND('Input and Output'!E4="Fish",'Input and Output'!E8="Cold Blooded"),0.1,AND('Input and Output'!E4="Fish",'Input and Output'!E8="Warm Blooded"),'Input and Output'!E4="Amphibians",0.1,0.02,'Input and Output'!E4="Birds",0.02,'Input and Output'!E4="Mammals",0.02,'Input and Output'!E4="Cnidaria",0.35)} -> 0.25 | E14: {=_xlfn.IFS('Input and Output'!F4="Algae",0.5,'Input and Output'!F4="Plants",0.5, 'Input and Output'!F4="Molluscs",0.25,'Input and Output'!F4="Worms",0.25, 'Input and Output'!F4="Arthropods", 0.25,'Input and Output'!F4="Crustaceans", 0.25,'Input and Output'!F4="Insects", 0.25,AND('Input and Output'!F4="Fish",'Input and Output'!F8="Cold Blooded"),0.1,AND('Input and Output'!F4="Fish",'Input and Output'!F8="Warm Blooded"),'Input and Output'!F4="Amphibians",0.1,0.02,'Input and Output'!F4="Birds",0.02,'Input and Output'!F4="Mammals",0.02,'Input and Output'!F4="Cnidaria",0.35)} -> 0.1 | F14: {=_xlfn.IFS('Input and Output'!G4="Algae",0.5,'Input and Output'!G4="Plants",0.5, 'Input and Output'!G4="Molluscs",0.25,'Input and Output'!G4="Worms",0.25, 'Input and Output'!G4="Arthropods", 0.25,'Input and Output'!G4="Crustaceans", 0.25,'Input and Output'!G4="Insects", 0.25,AND('Input and Output'!G4="Fish",'Input and Output'!G8="Cold Blooded"),0.1,AND('Input and Output'!G4="Fish",'Input and Output'!G8="Warm Blooded"),'Input and Output'!G4="Amphibians",0.1,0.02,'Input and Output'!G4="Birds",0.02,'Input and Output'!G4="Mammals",0.02,'Input and Output'!G4="Cnidaria",0.35)} -> 0.02 | H14: Alveolar Ventilation (L/day) | I14: Va | J14: =IFERROR(J13*0.7,"-") -> - | K14: =IFERROR(K13*0.7,"-") -> - | L14: =IFERROR(L13*0.7,"-") -> - | M14: =IFERROR(M13*0.7,"-") -> -
A15: Ion Ratio (Water) | B15: fn_w | C15: =1/(1+IF('Input and Output'!$D$12="Neutral",0,(10^(IF('Input and Output'!$D$12="Acidic",1,-1)*('Input and Output'!$B$12-'Input and Output'!$B$7))))) -> 0.35464755 | D15: =1/(1+IF('Input and Output'!$D$12="Neutral",0,(10^(IF('Input and Output'!$D$12="Acidic",1,-1)*('Input and Output'!$B$12-'Input and Output'!$B$7))))) -> 0.35464755 | E15: =1/(1+IF('Input and Output'!$D$12="Neutral",0,(10^(IF('Input and Output'!$D$12="Acidic",1,-1)*('Input and Output'!$B$12-'Input and Output'!$B$7))))) -> 0.35464755 | F15: =1/(1+IF('Input and Output'!$D$12="Neutral",0,(10^(IF('Input and Output'!$D$12="Acidic",1,-1)*('Input and Output'!$B$12-'Input and Output'!$B$7))))) -> 0.35464755 | H15: Ventilation resistance | I15: ρ_air | J15: =IFERROR(1/J14,"-") -> - | K15: =IFERROR(1/K14,"-") -> - | L15: =IFERROR(1/L14,"-") -> - | M15: =IFERROR(1/M14,"-") -> -
A16: Ion Ratio (Organism) | B16: fn_int | C16: =1/(1+10^(IF('Input and Output'!D12="Acidic",1,-1)*('Input and Output'!D9-'Input and Output'!B7))) -> 0.25746444 | D16: =1/(1+10^(IF('Input and Output'!D12="Acidic",1,-1)*('Input and Output'!E9-'Input and Output'!B7))) -> 0.25746444 | E16: =1/(1+10^(IF('Input and Output'!D12="Acidic",1,-1)*('Input and Output'!F9-'Input and Output'!B7))) -> 0.25746444 | F16: =1/(1+10^(IF('Input and Output'!D12="Acidic",1,-1)*('Input and Output'!G9-'Input and Output'!B7))) -> 0.25746444 | H16: blood:air parition coefficient | I16: Kba | J16: =10^(-1.069+0.456*'Input and Output'!$D14+1.083*'Input and Output'!$D15+3.738*'Input and Output'!$D16+2.58*'Input and Output'!$D17+0.376*'Input and Output'!$D19) -> 90202796 | K16: =10^(-1.069+0.456*'Input and Output'!$D14+1.083*'Input and Output'!$D15+3.738*'Input and Output'!$D16+2.58*'Input and Output'!$D17+0.376*'Input and Output'!$D19) -> 90202796 | L16: =10^(-1.069+0.456*'Input and Output'!$D14+1.083*'Input and Output'!$D15+3.738*'Input and Output'!$D16+2.58*'Input and Output'!$D17+0.376*'Input and Output'!$D19) -> 90202796 | M16: =10^(-1.069+0.456*'Input and Output'!$D14+1.083*'Input and Output'!$D15+3.738*'Input and Output'!$D16+2.58*'Input and Output'!$D17+0.376*'Input and Output'!$D19) -> 90202796
A17: Dow (Water) | B17: Dow_w | C17: =C15 * (10^'Input and Output'!$B4) + (1-C15) * (IF(ISBLANK('Input and Output'!$B5),(10^'Input and Output'!$B4),10^'Input and Output'!$B5)) -> 62816.154 | D17: =D15 * (10^'Input and Output'!$B4) + (1-D15) * (IF(ISBLANK('Input and Output'!$B5),(10^'Input and Output'!$B4),10^'Input and Output'!$B5)) -> 62816.154 | E17: =E15 * (10^'Input and Output'!$B4) + (1-E15) * (IF(ISBLANK('Input and Output'!$B5),(10^'Input and Output'!$B4),10^'Input and Output'!$B5)) -> 62816.154 | F17: =F15 * (10^'Input and Output'!$B4) + (1-F15) * (IF(ISBLANK('Input and Output'!$B5),(10^'Input and Output'!$B4),10^'Input and Output'!$B5)) -> 62816.154 | H17: Organism:Air Partition Coefficient | I17: Kia | J17: =Calculations!C43 * 10^(-('Input and Output'!$B4-'Input and Output'!$B6)) -> 97.589061 | K17: =Calculations!D43 * 10^(-('Input and Output'!$B4-'Input and Output'!$B6)) -> 1121.1031 | L17: =Calculations!E43 * 10^(-('Input and Output'!$B4-'Input and Output'!$B6)) -> 2129.7073 | M17: =Calculations!F43 * 10^(-('Input and Output'!$B4-'Input and Output'!$B6)) -> #N/A
A18: Dow (Organism | B18: Dow_int | C18: =C16 * (10^'Input and Output'!$B4) + (1-C16) * (IF(ISBLANK('Input and Output'!$B5),(10^'Input and Output'!$B4),10^'Input and Output'!$B5)) -> 49503.974 | D18: =D16 * (10^'Input and Output'!$B4) + (1-D16) * (IF(ISBLANK('Input and Output'!$B5),(10^'Input and Output'!$B4),10^'Input and Output'!$B5)) -> 49503.974 | E18: =E16 * (10^'Input and Output'!$B4) + (1-E16) * (IF(ISBLANK('Input and Output'!$B5),(10^'Input and Output'!$B4),10^'Input and Output'!$B5)) -> 49503.974 | F18: =F16 * (10^'Input and Output'!$B4) + (1-F16) * (IF(ISBLANK('Input and Output'!$B5),(10^'Input and Output'!$B4),10^'Input and Output'!$B5)) -> 49503.974 | H18: Lung resistance | I18: ρ_lung | J18: 0 | K18: 0 | L18: 0 | M18: 0
A19: Water Resistance | B19: ρ_H2O_0 | C19: =0.0028 -> 0.0028 | D19: =0.0028 -> 0.0028 | E19: =0.0028 -> 0.0028 | F19: =0.0028 -> 0.0028 | H19: Caridiac Output | I19: Q_pul | J19: {=IFERROR(_xlfn.IFS('Input and Output'!D4="Birds",290.7,'Input and Output'!D4="Mammals",200,'Input and Output'!D4="insects",100)*'Input and Output'!D5^0.75,"-")} -> - | K19: {=IFERROR(_xlfn.IFS('Input and Output'!E4="Birds",290.7,'Input and Output'!E4="Mammals",200,'Input and Output'!E4="insects",100)*'Input and Output'!E5^0.75,"-")} -> - | L19: {=IFERROR(_xlfn.IFS('Input and Output'!F4="Birds",290.7,'Input and Output'!F4="Mammals",200,'Input and Output'!F4="insects",100)*'Input and Output'!F5^0.75,"-")} -> - | M19: {=IFERROR(_xlfn.IFS('Input and Output'!G4="Birds",290.7,'Input and Output'!G4="Mammals",200,'Input and Output'!G4="insects",100)*'Input and Output'!G5^0.75,"-")} -> -
A20: Lipid Permiation Resistance | B20: ρ_CH2 | C20: 4600 | D20: 68 | E20: 68 | F20: 68 | H20: Inhalation uptake efficiency | I20: Einh | J20: =IFERROR(1/(1+(J19/J14)*(1/J16)),"-") -> - | K20: =IFERROR(1/(1+(K19/K14)*(1/K16)),"-") -> - | L20: =IFERROR(1/(1+(L19/L14)*(1/L16)),"-") -> - | M20: =IFERROR(1/(1+(M19/M14)*(1/M16)),"-") -> -
A21: Oxygen consumption rate | B21: VO2 | C21: =EXP(1)^19.1 * EXP(1)^(-5040/'Input and Output'!$B$11) * ('Input and Output'!D5)^0.75 -> 1.6092928 | D21: =EXP(1)^19.1 * EXP(1)^(-5040/'Input and Output'!$B$11) * ('Input and Output'!E5)^0.75 -> 5.4347155 | E21: =EXP(1)^19.1 * EXP(1)^(-5040/'Input and Output'!$B$11) * ('Input and Output'!F5)^0.75 -> 3.9700331 | F21: =EXP(1)^19.1 * EXP(1)^(-5040/'Input and Output'!$B$11) * ('Input and Output'!G5)^0.75 -> 9.0497184 | H21: ventilation–perfusion coefficient | I21: γ_air | J21: =IFERROR(1/(J20*J14),"-") -> - | K21: =IFERROR(1/(K20*K14),"-") -> - | L21: =IFERROR(1/(L20*L14),"-") -> - | M21: =IFERROR(1/(M20*M14),"-") -> -
A22: Dissolved oxygen concentration | B22: C_ox | C22: =EXP(1)^-10.6 * EXP(1)^(1743.3/'Input and Output'!B11) -> 0.0095599704 | D22: =EXP(1)^-10.6 * EXP(1)^(1743.3/'Input and Output'!B11) -> 0.0095599704 | E22: =EXP(1)^-10.6 * EXP(1)^(1743.3/'Input and Output'!B11) -> 0.0095599704 | F22: =EXP(1)^-10.6 * EXP(1)^(1743.3/'Input and Output'!B11) -> 0.0095599704 | H22: Glomerular Filtration rate (L/ | I22: GFR_m | J22: {=IFERROR(_xlfn.IFS('Input and Output'!D4="Birds",4.5*('Input and Output'!D5/1000)^-0.25,'Input and Output'!D4="Mammals",2.82*('Input and Output'!D5/1000)^-0.25,'Input and Output'!D4="Worms",0.2*('Input and Output'!D5/1000)^-0.25),"-")} -> - | K22: {=IFERROR(_xlfn.IFS('Input and Output'!E4="Birds",4.5*('Input and Output'!E5/1000)^-0.25,'Input and Output'!E4="Mammals",2.82*('Input and Output'!E5/1000)^-0.25,'Input and Output'!E4="Worms",0.2*('Input and Output'!E5/1000)^-0.25),"-")} -> - | L22: {=IFERROR(_xlfn.IFS('Input and Output'!F4="Birds",4.5*('Input and Output'!F5/1000)^-0.25,'Input and Output'!F4="Mammals",2.82*('Input and Output'!F5/1000)^-0.25,'Input and Output'!F4="Worms",0.2*('Input and Output'!F5/1000)^-0.25),"-")} -> - | M22: {=IFERROR(_xlfn.IFS('Input and Output'!G4="Birds",4.5*('Input and Output'!G5/1000)^-0.25,'Input and Output'!G4="Mammals",2.82*('Input and Output'!G5/1000)^-0.25,'Input and Output'!G4="Worms",0.2*('Input and Output'!G5/1000)^-0.25),"-")} -> -
A23: Water absorption-excretion coefficient | B23: γ_0 | C23: =(C21/(0.71 * $C$22)) * 1/'Input and Output'!D5^0.75 -> 983.67521 | D23: =(D21/(0.71 * $C$22)) * 1/'Input and Output'!E5^0.75 -> 983.67521 | E23: =(E21/(0.71 * $C$22)) * 1/'Input and Output'!F5^0.75 -> 983.67521 | F23: =(F21/(0.71 * $C$22)) * 1/'Input and Output'!G5^0.75 -> 983.67521 | H23: Fraction of neutral lipid in blood | I23: fnl_i | J23: =Calculations!C26*0.1 -> 0 | K23: =Calculations!D26*0.1 -> 0.002 | L23: =Calculations!E26*0.1 -> 0.004 | M23: =Calculations!F26*0.1 -> #N/A
A24: Fraction of ingested food assimilated | B24: p_1 | C24: {=_xlfn.IFS('Input and Output'!D7="Photosynthesis",0,'Input and Output'!D7="Detritus",0.2,'Input and Output'!D7="Herbivore",0.4,'Input and Output'!D7="Carnivore",0.8)} -> 0 | D24: {=_xlfn.IFS('Input and Output'!E7="Photosynthesis",0,'Input and Output'!E7="Detritus",0.2,'Input and Output'!E7="Herbivore",0.4,'Input and Output'!E7="Carnivore",0.8)} -> 0.4 | E24: {=_xlfn.IFS('Input and Output'!F7="Photosynthesis",0,'Input and Output'!F7="Detritus",0.2,'Input and Output'!F7="Herbivore",0.4,'Input and Output'!F7="Carnivore",0.8)} -> 0.8 | F24: {=_xlfn.IFS('Input and Output'!G7="Photosynthesis",0,'Input and Output'!G7="Detritus",0.2,'Input and Output'!G7="Herbivore",0.4,'Input and Output'!G7="Carnivore",0.8)} -> 0.8 | H24: Fraction of polar lipid in blood | I24: fpl_i | J24: =Calculations!C27*0.1 -> 0.001 | K24: =Calculations!D27*0.1 -> 0.001 | L24: =Calculations!E27*0.1 -> 0.001 | M24: =Calculations!F27*0.1 -> #N/A
A25: Water layer resistance from/to food | B25: ρ_H2O_1 | C25: 1.1e-05 | D25: 1.1e-05 | E25: 1.1e-05 | F25: 1.1e-05 | H25: Fraction of protein in blood | I25: fprot_i | J25: =Calculations!C28*0.1 -> 0.004 | K25: =Calculations!D28*0.1 -> 0.013 | L25: =Calculations!E28*0.1 -> 0.018 | M25: =Calculations!F28*0.1 -> #N/A
A26: Fraction of neutral lipid in organism i | B26: fnl_i | C26: {=_xlfn.IFS('Input and Output'!D4="Algae",0,'Input and Output'!D4="Plants",0,'Input and Output'!D4="Worms",0.01,'Input and Output'!D4="Molluscs",0,'Input and Output'!D4="Arthropods",0.02,'Input and Output'!D4="Crustaceans",0.02,'Input and Output'!D4="Insects",0.02,'Input and Output'!D4="Fish",0.04,'Input and Output'!D4="Amphibians",0.04,'Input and Output'!D4="Birds",0.09,'Input and Output'!D4="mammals",0.09, 'Input and Output'!D4="Cnidaria",0.00002)} -> 0 | D26: {=_xlfn.IFS('Input and Output'!E4="Algae",0,'Input and Output'!E4="Plants",0,'Input and Output'!E4="Worms",0.01,'Input and Output'!E4="Molluscs",0,'Input and Output'!E4="Arthropods",0.02,'Input and Output'!E4="Crustaceans",0.02,'Input and Output'!E4="Insects",0.02,'Input and Output'!E4="Fish",0.04,'Input and Output'!E4="Amphibians",0.04,'Input and Output'!E4="Birds",0.09,'Input and Output'!E4="mammals",0.09, 'Input and Output'!E4="Cnidaria",0.00002)} -> 0.02 | E26: {=_xlfn.IFS('Input and Output'!F4="Algae",0,'Input and Output'!F4="Plants",0,'Input and Output'!F4="Worms",0.01,'Input and Output'!F4="Molluscs",0,'Input and Output'!F4="Arthropods",0.02,'Input and Output'!F4="Crustaceans",0.02,'Input and Output'!F4="Insects",0.02,'Input and Output'!F4="Fish",0.04,'Input and Output'!F4="Amphibians",0.04,'Input and Output'!F4="Birds",0.09,'Input and Output'!F4="mammals",0.09, 'Input and Output'!F4="Cnidaria",0.00002)} -> 0.04 | F26: {=_xlfn.IFS('Input and Output'!G4="Algae",0,'Input and Output'!G4="Plants",0,'Input and Output'!G4="Worms",0.01,'Input and Output'!G4="Molluscs",0,'Input and Output'!G4="Arthropods",0.02,'Input and Output'!G4="Crustaceans",0.02,'Input and Output'!G4="Insects",0.02,'Input and Output'!G4="Fish",0.04,'Input and Output'!G4="Amphibians",0.04,'Input and Output'!G4="Birds",0.09,'Input and Output'!G4="mammals",0.09, 'Input and Output'!G4="Cnidaria",0.00002)} -> #N/A | H26: Fraction of water in blood | I26: fw_i | J26: =1-SUM(J23:J25) -> 0.995 | K26: =1-SUM(K23:K25) -> 0.984 | L26: =1-SUM(L23:L25) -> 0.977 | M26: =1-SUM(M23:M25) -> #N/A
A27: Fraction of polar lipid in organism i | B27: fpl_i | C27: {=_xlfn.IFS('Input and Output'!D4="Algae",0.01,'Input and Output'!D4="Plants",0.01,'Input and Output'!D4="Worms",0.01,'Input and Output'!D4="Molluscs",0.01,'Input and Output'!D4="Arthropods",0.01,'Input and Output'!D4="Crustaceans",0.01,'Input and Output'!D4="Insects",0.01,'Input and Output'!D4="Fish",0.01,'Input and Output'!D4="Amphibians",0.01,'Input and Output'!D4="Birds",0.01,'Input and Output'!D4="Mammals",0.01,'Input and Output'!D4="Cnidaria",0.00028)} -> 0.01 | D27: {=_xlfn.IFS('Input and Output'!E4="Algae",0.01,'Input and Output'!E4="Plants",0.01,'Input and Output'!E4="Worms",0.01,'Input and Output'!E4="Molluscs",0.01,'Input and Output'!E4="Arthropods",0.01,'Input and Output'!E4="Crustaceans",0.01,'Input and Output'!E4="Insects",0.01,'Input and Output'!E4="Fish",0.01,'Input and Output'!E4="Amphibians",0.01,'Input and Output'!E4="Birds",0.01,'Input and Output'!E4="Mammals",0.01,'Input and Output'!E4="Cnidaria",0.00028)} -> 0.01 | E27: {=_xlfn.IFS('Input and Output'!F4="Algae",0.01,'Input and Output'!F4="Plants",0.01,'Input and Output'!F4="Worms",0.01,'Input and Output'!F4="Molluscs",0.01,'Input and Output'!F4="Arthropods",0.01,'Input and Output'!F4="Crustaceans",0.01,'Input and Output'!F4="Insects",0.01,'Input and Output'!F4="Fish",0.01,'Input and Output'!F4="Amphibians",0.01,'Input and Output'!F4="Birds",0.01,'Input and Output'!F4="Mammals",0.01,'Input and Output'!F4="Cnidaria",0.00028)} -> 0.01 | F27: {=_xlfn.IFS('Input and Output'!G4="Algae",0.01,'Input and Output'!G4="Plants",0.01,'Input and Output'!G4="Worms",0.01,'Input and Output'!G4="Molluscs",0.01,'Input and Output'!G4="Arthropods",0.01,'Input and Output'!G4="Crustaceans",0.01,'Input and Output'!G4="Insects",0.01,'Input and Output'!G4="Fish",0.01,'Input and Output'!G4="Amphibians",0.01,'Input and Output'!G4="Birds",0.01,'Input and Output'!G4="Mammals",0.01,'Input and Output'!G4="Cnidaria",0.00028)} -> #N/A | H27: Unbound Fraction | I27: FU | J27: =1 / ( 1 + (Calculations!C37*(J25*0.7)) + (Calculations!C38*(J25*0.3)) + (Calculations!C34*(J23+J24)) ) -> 0.01934854 | K27: =1 / ( 1 + (Calculations!D37*(K25*0.7)) + (Calculations!D38*(K25*0.3)) + (Calculations!D34*(K23+K24)) ) -> 0.0065212287 | L27: =1 / ( 1 + (Calculations!E37*(L25*0.7)) + (Calculations!E38*(L25*0.3)) + (Calculations!E34*(L23+L24)) ) -> 0.0039396808 | M27: =1 / ( 1 + (Calculations!F37*(M25*0.7)) + (Calculations!F38*(M25*0.3)) + (Calculations!F34*(M23+M24)) ) -> #N/A
A28: Fraction of protein in organism i | B28: fprot_i | C28: {=_xlfn.IFS('Input and Output'!D4="Algae",0.04,'Input and Output'!D4="Plants",0.04,'Input and Output'!D4="worms",0.1,'Input and Output'!D4="Molluscs",0.1,'Input and Output'!D4="Arthropods",0.13,'Input and Output'!D4="Insects",0.13,'Input and Output'!D4="crustaceans",0.13,'Input and Output'!D4="Fish",0.18,'Input and Output'!D4="Amphibians",0.18,'Input and Output'!D4="Birds",0.21,'Input and Output'!D4="Mammals",0.21,'Input and Output'!D4="Cnidaria",0.0024)} -> 0.04 | D28: {=_xlfn.IFS('Input and Output'!E4="Algae",0.04,'Input and Output'!E4="Plants",0.04,'Input and Output'!E4="worms",0.1,'Input and Output'!E4="Molluscs",0.1,'Input and Output'!E4="Arthropods",0.13,'Input and Output'!E4="Insects",0.13,'Input and Output'!E4="crustaceans",0.13,'Input and Output'!E4="Fish",0.18,'Input and Output'!E4="Amphibians",0.18,'Input and Output'!E4="Birds",0.21,'Input and Output'!E4="Mammals",0.21,'Input and Output'!E4="Cnidaria",0.0024)} -> 0.13 | E28: {=_xlfn.IFS('Input and Output'!F4="Algae",0.04,'Input and Output'!F4="Plants",0.04,'Input and Output'!F4="worms",0.1,'Input and Output'!F4="Molluscs",0.1,'Input and Output'!F4="Arthropods",0.13,'Input and Output'!F4="Insects",0.13,'Input and Output'!F4="crustaceans",0.13,'Input and Output'!F4="Fish",0.18,'Input and Output'!F4="Amphibians",0.18,'Input and Output'!F4="Birds",0.21,'Input and Output'!F4="Mammals",0.21,'Input and Output'!F4="Cnidaria",0.0024)} -> 0.18 | F28: {=_xlfn.IFS('Input and Output'!G4="Algae",0.04,'Input and Output'!G4="Plants",0.04,'Input and Output'!G4="worms",0.1,'Input and Output'!G4="Molluscs",0.1,'Input and Output'!G4="Arthropods",0.13,'Input and Output'!G4="Insects",0.13,'Input and Output'!G4="crustaceans",0.13,'Input and Output'!G4="Fish",0.18,'Input and Output'!G4="Amphibians",0.18,'Input and Output'!G4="Birds",0.21,'Input and Output'!G4="Mammals",0.21,'Input and Output'!G4="Cnidaria",0.0024)} -> #N/A | H28: Body:Blood Partition Coefficient | I28: k_bb | J28: =Calculations!C43/(J26+J25*Calculations!C40+(J24+J23)*Calculations!C34) -> 1.9321261 | K28: =Calculations!D43/(K26+K25*Calculations!D40+(K24+K23)*Calculations!D34) -> 7.4976463 | L28: =Calculations!E43/(L26+L25*Calculations!E40+(L24+L23)*Calculations!E34) -> 8.5688588 | M28: =Calculations!F43/(M26+M25*Calculations!F40+(M24+M23)*Calculations!F34) -> #N/A
A29: Fraction of water in organism i | B29: fw_i | C29: {=_xlfn.IFS('Input and Output'!D4="Algae",0.9,'Input and Output'!D4="Plants",0.8,'Input and Output'!D4="worms",0.85,'Input and Output'!D4="Molluscs",0.85,'Input and Output'!D4="Arthropods",0.8,'Input and Output'!D4="Crustaceans",0.8,'Input and Output'!D4="Insects",0.8,'Input and Output'!D4="Fish",0.75,'Input and Output'!D4="Amphibians",0.75,'Input and Output'!D4="Birds",0.67,'Input and Output'!D4="Mammals",0.67, 'Input and Output'!D4="Cnidaria",0.96)} -> 0.8 | D29: {=_xlfn.IFS('Input and Output'!E4="Algae",0.9,'Input and Output'!E4="Plants",0.8,'Input and Output'!E4="worms",0.85,'Input and Output'!E4="Molluscs",0.85,'Input and Output'!E4="Arthropods",0.8,'Input and Output'!E4="Crustaceans",0.8,'Input and Output'!E4="Insects",0.8,'Input and Output'!E4="Fish",0.75,'Input and Output'!E4="Amphibians",0.75,'Input and Output'!E4="Birds",0.67,'Input and Output'!E4="Mammals",0.67, 'Input and Output'!E4="Cnidaria",0.96)} -> 0.8 | E29: {=_xlfn.IFS('Input and Output'!F4="Algae",0.9,'Input and Output'!F4="Plants",0.8,'Input and Output'!F4="worms",0.85,'Input and Output'!F4="Molluscs",0.85,'Input and Output'!F4="Arthropods",0.8,'Input and Output'!F4="Crustaceans",0.8,'Input and Output'!F4="Insects",0.8,'Input and Output'!F4="Fish",0.75,'Input and Output'!F4="Amphibians",0.75,'Input and Output'!F4="Birds",0.67,'Input and Output'!F4="Mammals",0.67, 'Input and Output'!F4="Cnidaria",0.96)} -> 0.75 | F29: {=_xlfn.IFS('Input and Output'!G4="Algae",0.9,'Input and Output'!G4="Plants",0.8,'Input and Output'!G4="worms",0.85,'Input and Output'!G4="Molluscs",0.85,'Input and Output'!G4="Arthropods",0.8,'Input and Output'!G4="Crustaceans",0.8,'Input and Output'!G4="Insects",0.8,'Input and Output'!G4="Fish",0.75,'Input and Output'!G4="Amphibians",0.75,'Input and Output'!G4="Birds",0.67,'Input and Output'!G4="Mammals",0.67, 'Input and Output'!G4="Cnidaria",0.96)} -> #N/A | H29: Urine pH | I29: pH_u | J29: {=IFERROR(_xlfn.IFS('Input and Output'!D4="Birds",7,'Input and Output'!D4="Mammals",6.5,'Input and Output'!D4="Worms",7),"-")} -> - | K29: {=IFERROR(_xlfn.IFS('Input and Output'!E4="Birds",7,'Input and Output'!E4="Mammals",6.5),"-")} -> - | L29: {=IFERROR(_xlfn.IFS('Input and Output'!F4="Birds",7,'Input and Output'!F4="Mammals",6.5),"-")} -> - | M29: {=IFERROR(_xlfn.IFS('Input and Output'!G4="Birds",7,'Input and Output'!G4="Mammals",6.5),"-")} -> -
A30: Lipid fraction of food | B30: f_CH2_i | C30: {=IF(SUM(B26:B27)>=0,_xlfn.IFS('Input and Output'!D7="Photosynthesis",0,'Input and Output'!D7="Detritus",0.01,'Input and Output'!D7="Herbivore",0.01,'Input and Output'!D7="Carnivore",0.05))} -> 0 | D30: {=IF(SUM(C26:C27)>=0,_xlfn.IFS('Input and Output'!E7="Photosynthesis",0,'Input and Output'!E7="Detritus",0.01,'Input and Output'!E7="Herbivore",0.01,'Input and Output'!E7="Carnivore",0.05))} -> 0.01 | E30: {=IF(SUM(D26:D27)>=0,_xlfn.IFS('Input and Output'!F7="Photosynthesis",0,'Input and Output'!F7="Detritus",0.01,'Input and Output'!F7="Herbivore",0.01,'Input and Output'!F7="Carnivore",0.05))} -> 0.05 | F30: {=IF(SUM(E26:E27)>=0,_xlfn.IFS('Input and Output'!G7="Photosynthesis",0,'Input and Output'!G7="Detritus",0.01,'Input and Output'!G7="Herbivore",0.01,'Input and Output'!G7="Carnivore",0.05))} -> 0.05 | H30: Henderson-Hasselbalch Fraction | I30: f_urine | J30: =IFERROR(IF('Input and Output'!$D12="Acidic", 1/(1+10^(J29 - 'Input and Output'!$B7)), IF('Input and Output'!$D12="Basic", 1/(1+10^('Input and Output'!$B7 - J29)), 1)),"-") -> - | K30: =IFERROR(IF('Input and Output'!$D12="Acidic", 1/(1+10^(K29 - 'Input and Output'!$B7)), IF('Input and Output'!$D12="Basic", 1/(1+10^('Input and Output'!$B7 - K29)), 1)),"-") -> - | L30: =IFERROR(IF('Input and Output'!$D12="Acidic", 1/(1+10^(L29 - 'Input and Output'!$B7)), IF('Input and Output'!$D12="Basic", 1/(1+10^('Input and Output'!$B7 - L29)), 1)),"-") -> - | M30: =IFERROR(IF('Input and Output'!$D12="Acidic", 1/(1+10^(M29 - 'Input and Output'!$B7)), IF('Input and Output'!$D12="Basic", 1/(1+10^('Input and Output'!$B7 - M29)), 1)),"-") -> -
A31: Scaling coefficient for production | B31: γ_p | C31: 0.00075 | D31: 0.00075 | E31: 0.00075 | F31: 0.00075 | H31: Dow (Urine) | I31: Dow_u | J31: =IFERROR(J30 * (10^#REF!) + (1-J30) * (IF(ISBLANK(#REF!),(10^#REF!),10^#REF!)),"-") -> - | K31: =IFERROR(K30 * (10^#REF!) + (1-K30) * (IF(ISBLANK(#REF!),(10^#REF!),10^#REF!)),"-") -> - | L31: =IFERROR(L30 * (10^#REF!) + (1-L30) * (IF(ISBLANK(#REF!),(10^#REF!),10^#REF!)),"-") -> - | M31: =IFERROR(M30 * (10^#REF!) + (1-M30) * (IF(ISBLANK(#REF!),(10^#REF!),10^#REF!)),"-") -> -
A32: Food ingestion coefficient | B32: k_n | C32: =IFERROR((C13 * C31) / (C14 * C24),0) -> 0 | D32: =(D13 * D31) / (D14 * D24) -> 0.0075 | E32: =(E13 * E31) / (E14 * E24) -> 0.009375 | F32: =(F13 * F31) / (F14 * F24) -> 0.046875 | H32: Passive Reabsorption | I32: F_Reabs | J32: =IFERROR(J30*(1/(1+10^-(LOG10(J31)-1))),"-") -> - | K32: =IFERROR(K30*(1/(1+10^-(LOG10(K31)-1))),"-") -> - | L32: =IFERROR(L30*(1/(1+10^-(LOG10(L31)-1))),"-") -> - | M32: =IFERROR(M30*(1/(1+10^-(LOG10(M31)-1))),"-") -> -
A33: Biomass (re)production coefficient | B33: γ_2 | C33: 0.0006 | D33: 0.0006 | E33: 0.0006 | F33: 0.0006
A34: Lipid-water distribution coefficient in organism | B34: Dlip_w | C34: =C18 -> 49503.974 | D34: =D18 -> 49503.974 | E34: =E18 -> 49503.974 | F34: =F18 -> 49503.974
A35: Membrane-water distribution coefficient in organism | B35: Dmw_1 | C35: =2*C18^0.63 -> 1814.0666 | D35: =2*D18^0.63 -> 1814.0666 | E35: =2*E18^0.63 -> 1814.0666 | F35: =2*F18^0.63 -> 1814.0666
A36: Membrane-water distribution coefficient in organism | B36: Dmw_2 | C36: =10^(0.44+0.99*Calculations!F3-0.69*Calculations!F4-0.19*Calculations!F5-2.82*Calculations!F6+2.83*Calculations!F7-1.14*Calculations!F8+2.95*Calculations!F9) -> 8192.9254 | D36: =10^(0.44+0.99*Calculations!F3-0.69*Calculations!F4-0.19*Calculations!F5-2.82*Calculations!F6+2.83*Calculations!F7-1.14*Calculations!F8+2.95*Calculations!F9) -> 8192.9254 | E36: =10^(0.44+0.99*Calculations!F3-0.69*Calculations!F4-0.19*Calculations!F5-2.82*Calculations!F6+2.83*Calculations!F7-1.14*Calculations!F8+2.95*Calculations!F9) -> 8192.9254 | F36: =10^(0.44+0.99*Calculations!F3-0.69*Calculations!F4-0.19*Calculations!F5-2.82*Calculations!F6+2.83*Calculations!F7-1.14*Calculations!F8+2.95*Calculations!F9) -> 8192.9254
A37: Bovine serum albumin-water distribution coefficient in organism | B37: D_BSAW | C37: =10^(0.85+0.63*Calculations!F3-0.63*Calculations!F4-0.05*Calculations!F5-2.08*Calculations!F6+2.06*Calculations!F7-1.16*Calculations!F8+3.13*Calculations!F9) -> 261.07627 | D37: =10^(0.85+0.63*Calculations!F3-0.63*Calculations!F4-0.05*Calculations!F5-2.08*Calculations!F6+2.06*Calculations!F7-1.16*Calculations!F8+3.13*Calculations!F9) -> 261.07627 | E37: =10^(0.85+0.63*Calculations!F3-0.63*Calculations!F4-0.05*Calculations!F5-2.08*Calculations!F6+2.06*Calculations!F7-1.16*Calculations!F8+3.13*Calculations!F9) -> 261.07627 | F37: =10^(0.85+0.63*Calculations!F3-0.63*Calculations!F4-0.05*Calculations!F5-2.08*Calculations!F6+2.06*Calculations!F7-1.16*Calculations!F8+3.13*Calculations!F9) -> 261.07627
A38: Muscle protein-water distribution coefficient in organism | B38: D_MPW | C38: =10^(-0.24+0.68*Calculations!F3-0.76*Calculations!F4-0.2*Calculations!F5-2.29*Calculations!F6+2.51*Calculations!F7-0.68*Calculations!F8+2.89*Calculations!F9) -> 373.74862 | D38: =10^(-0.24+0.68*Calculations!F3-0.76*Calculations!F4-0.2*Calculations!F5-2.29*Calculations!F6+2.51*Calculations!F7-0.68*Calculations!F8+2.89*Calculations!F9) -> 373.74862 | E38: =10^(-0.24+0.68*Calculations!F3-0.76*Calculations!F4-0.2*Calculations!F5-2.29*Calculations!F6+2.51*Calculations!F7-0.68*Calculations!F8+2.89*Calculations!F9) -> 373.74862 | F38: =10^(-0.24+0.68*Calculations!F3-0.76*Calculations!F4-0.2*Calculations!F5-2.29*Calculations!F6+2.51*Calculations!F7-0.68*Calculations!F8+2.89*Calculations!F9) -> 373.74862
A39: Protein-water distribution coefficient in organism | B39: Dprot_w | C39: =(10^'Input and Output'!$B4)^0.63 -> 1832.9389 | D39: =(10^'Input and Output'!$B4)^0.63 -> 1832.9389 | E39: =(10^'Input and Output'!$B4)^0.63 -> 1832.9389 | F39: =(10^'Input and Output'!$B4)^0.63 -> 1832.9389
A40: Logged Bovine serum albumin-water distribution coefficient in organism | B40: logD_BSAW | C40: =0.85 + 0.63 * Calculations!F3 - 0.63 * Calculations!F4- 0.05 * Calculations!F5 - 2.08 * Calculations!F6 + 2.06 * Calculations!F7 - 1.16 * Calculations!F8 + 3.13 * Calculations!F9 -> 2.4167674 | D40: =0.85 + 0.63 * Calculations!F3 - 0.63 * Calculations!F4- 0.05 * Calculations!F5 - 2.08 * Calculations!F6 + 2.06 * Calculations!F7 - 1.16 * Calculations!F8 + 3.13 * Calculations!F9 -> 2.4167674 | E40: =0.85 + 0.63 * Calculations!F3 - 0.63 * Calculations!F4- 0.05 * Calculations!F5 - 2.08 * Calculations!F6 + 2.06 * Calculations!F7 - 1.16 * Calculations!F8 + 3.13 * Calculations!F9 -> 2.4167674 | F40: =0.85 + 0.63 * Calculations!F3 - 0.63 * Calculations!F4- 0.05 * Calculations!F5 - 2.08 * Calculations!F6 + 2.06 * Calculations!F7 - 1.16 * Calculations!F8 + 3.13 * Calculations!F9 -> 2.4167674
A41: Logged Muscle protein-water distribution coefficient in organism | B41: logD_MPW | C41: =-0.24 + 0.68 * Calculations!F3 - 0.76 * Calculations!F4- 0.2 * Calculations!F5 - 2.29 * Calculations!F6 + 2.51 * Calculations!F7 - 0.68 * Calculations!F8 + 2.89 * Calculations!F9 -> 2.5725796 | D41: =-0.24 + 0.68 * Calculations!F3 - 0.76 * Calculations!F4- 0.2 * Calculations!F5 - 2.29 * Calculations!F6 + 2.51 * Calculations!F7 - 0.68 * Calculations!F8 + 2.89 * Calculations!F9 -> 2.5725796 | E41: =-0.24 + 0.68 * Calculations!F3 - 0.76 * Calculations!F4- 0.2 * Calculations!F5 - 2.29 * Calculations!F6 + 2.51 * Calculations!F7 - 0.68 * Calculations!F8 + 2.89 * Calculations!F9 -> 2.5725796 | F41: =-0.24 + 0.68 * Calculations!F3 - 0.76 * Calculations!F4- 0.2 * Calculations!F5 - 2.29 * Calculations!F6 + 2.51 * Calculations!F7 - 0.68 * Calculations!F8 + 2.89 * Calculations!F9 -> 2.5725796
...

Sheet Kinetic Model
A1: Timestep | B1: {=_xlfn.IFS('Input and Output'!$F$14="Seconds",86400,'Input and Output'!$F$14="Minuites",1440,'Input and Output'!$F$14="Hours",24,'Input and Output'!$F$14="Days",1)*'Input and Output'!F15} -> 24 | C1: Conc. Change (ug/kg wet weight/day) | H1: Conc (ug/kg wet weight)
B2: t | C2: ='Input and Output'!D4 -> Plants | D2: ='Input and Output'!E4 -> Crustaceans | E2: ='Input and Output'!F4 -> Fish | F2: ='Input and Output'!G4 -> None | H2: =IF(C2= "None","",C2) -> Plants | I2: =IF(D2= "None","",D2) -> Crustaceans | J2: =IF(E2= "None","",E2) -> Fish | K2: =IF(F2= "None","",F2)
B3: 0 | C3: =(('Input and Output'!B$23*'Input and Output'!$B$10)+('Input and Output'!B$24*Calculations!$C$5)+('Input and Output'!B$25*Calculations!$C$6)+('Input and Output'!B$26*0))-(SUM('Input and Output'!B$27:B$32)*0) -> 312.83649 | D3: =(('Input and Output'!C$23*'Input and Output'!$B$10)+('Input and Output'!C$24*Calculations!$C$5)+('Input and Output'!C$25*Calculations!$C$6)+('Input and Output'!C$26*0))-(SUM('Input and Output'!C$27:C$32)*0) -> 3279.2143 | E3: =(('Input and Output'!D$23*'Input and Output'!$B$10)+('Input and Output'!D$24*Calculations!$C$5)+('Input and Output'!D$25*Calculations!$C$6)+('Input and Output'!D$26*0))-(SUM('Input and Output'!D$27:D$32)*0) -> 3641.084 | F3: =(('Input and Output'!E$23*'Input and Output'!$B$10)+('Input and Output'!E$24*Calculations!$C$5)+('Input and Output'!E$25*Calculations!$C$6)+('Input and Output'!E$26*0))-(SUM('Input and Output'!E$27:E$32)*0) -> 0 | H3: =IF(H$2="",NA(),C3*$B3) -> 0 | I3: =IF(I$2="",NA(),D3*$B3) -> 0 | J3: =IF(J$2="",NA(),E3*$B3) -> 0 | K3: =IF(K$2="",NA(),F3*$B3) -> #N/A
A4: 1 | B4: =A4/$B$1 -> 0.041666667 | C4: =(('Input and Output'!B$23*'Input and Output'!$B$10)+('Input and Output'!B$24*Calculations!$C$5)+('Input and Output'!B$25*Calculations!$C$6)+('Input and Output'!B$26*(IF('Input and Output'!D$7="Detritus",Calculations!$C$4,G4))-(SUM('Input and Output'!B$27:B$32))*H3)) -> 312.83649 | D4: =(('Input and Output'!C$23*'Input and Output'!$B$10)+('Input and Output'!C$24*Calculations!$C$5)+('Input and Output'!C$25*Calculations!$C$6)+('Input and Output'!C$26*(IF('Input and Output'!E$7="Detritus",Calculations!$C$4,H4))-(SUM('Input and Output'!C$27:C$32))*I3)) -> 3279.4831 | E4: =(('Input and Output'!D$23*'Input and Output'!$B$10)+('Input and Output'!D$24*Calculations!$C$5)+('Input and Output'!D$25*Calculations!$C$6)+('Input and Output'!D$26*(IF('Input and Output'!F$7="Detritus",Calculations!$C$4,I4))-(SUM('Input and Output'!D$27:D$32))*J3)) -> 3644.4765 | F4: =(('Input and Output'!E$23*'Input and Output'!$B$10)+('Input and Output'!E$24*Calculations!$C$5)+('Input and Output'!E$25*Calculations!$C$6)+('Input and Output'!E$26*(IF('Input and Output'!G$7="Detritus",Calculations!$C$4,J4))-(SUM('Input and Output'!E$27:E$32))*K3)) -> #N/A | H4: =IF(H$2="",NA(),C4*$B4+H3) -> 13.034854 | I4: =IF(I$2="",NA(),D4*$B4+I3) -> 136.64513 | J4: =IF(J$2="",NA(),E4*$B4+J3) -> 151.85319 | K4: =IF(K$2="",NA(),F4*$B4+K3) -> #N/A
A5: 2 | B5: =A5/$B$1 -> 0.083333333 | C5: =(('Input and Output'!B$23*'Input and Output'!$B$10)+('Input and Output'!B$24*Calculations!$C$5)+('Input and Output'!B$25*Calculations!$C$6)+('Input and Output'!B$26*(IF('Input and Output'!D$7="Detritus",Calculations!$C$4,G5))-(SUM('Input and Output'!B$27:B$32))*H4)) -> 312.82393 | D5: =(('Input and Output'!C$23*'Input and Output'!$B$10)+('Input and Output'!C$24*Calculations!$C$5)+('Input and Output'!C$25*Calculations!$C$6)+('Input and Output'!C$26*(IF('Input and Output'!E$7="Detritus",Calculations!$C$4,H5))-(SUM('Input and Output'!C$27:C$32))*I4)) -> 3279.5624 | E5: =(('Input and Output'!D$23*'Input and Output'!$B$10)+('Input and Output'!D$24*Calculations!$C$5)+('Input and Output'!D$25*Calculations!$C$6)+('Input and Output'!D$26*(IF('Input and Output'!F$7="Detritus",Calculations!$C$4,I5))-(SUM('Input and Output'!D$27:D$32))*J4)) -> 3642.7502 | F5: =(('Input and Output'!E$23*'Input and Output'!$B$10)+('Input and Output'!E$24*Calculations!$C$5)+('Input and Output'!E$25*Calculations!$C$6)+('Input and Output'!E$26*(IF('Input and Output'!G$7="Detritus",Calculations!$C$4,J5))-(SUM('Input and Output'!E$27:E$32))*K4)) -> #N/A | H5: =IF(H$2="",NA(),C5*$B5+H4) -> 39.103514 | I5: =IF(I$2="",NA(),D5*$B5+I4) -> 409.94199 | J5: =IF(J$2="",NA(),E5*$B5+J4) -> 455.4157 | K5: =IF(K$2="",NA(),F5*$B5+K4) -> #N/A
A6: 3 | B6: =A6/$B$1 -> 0.125 | C6: =(('Input and Output'!B$23*'Input and Output'!$B$10)+('Input and Output'!B$24*Calculations!$C$5)+('Input and Output'!B$25*Calculations!$C$6)+('Input and Output'!B$26*(IF('Input and Output'!D$7="Detritus",Calculations!$C$4,G6))-(SUM('Input and Output'!B$27:B$32))*H5)) -> 312.79879 | D6: =(('Input and Output'!C$23*'Input and Output'!$B$10)+('Input and Output'!C$24*Calculations!$C$5)+('Input and Output'!C$25*Calculations!$C$6)+('Input and Output'!C$26*(IF('Input and Output'!E$7="Detritus",Calculations!$C$4,H6))-(SUM('Input and Output'!C$27:C$32))*I5)) -> 3279.4521 | E6: =(('Input and Output'!D$23*'Input and Output'!$B$10)+('Input and Output'!D$24*Calculations!$C$5)+('Input and Output'!D$25*Calculations!$C$6)+('Input and Output'!D$26*(IF('Input and Output'!F$7="Detritus",Calculations!$C$4,I6))-(SUM('Input and Output'!D$27:D$32))*J5)) -> 3635.9126 | F6: =(('Input and Output'!E$23*'Input and Output'!$B$10)+('Input and Output'!E$24*Calculations!$C$5)+('Input and Output'!E$25*Calculations!$C$6)+('Input and Output'!E$26*(IF('Input and Output'!G$7="Detritus",Calculations!$C$4,J6))-(SUM('Input and Output'!E$27:E$32))*K5)) -> #N/A | H6: =IF(H$2="",NA(),C6*$B6+H5) -> 78.203364 | I6: =IF(I$2="",NA(),D6*$B6+I5) -> 819.87351 | J6: =IF(J$2="",NA(),E6*$B6+J5) -> 909.90477 | K6: =IF(K$2="",NA(),F6*$B6+K5) -> #N/A
A7: 4 | B7: =A7/$B$1 -> 0.16666667 | C7: =(('Input and Output'!B$23*'Input and Output'!$B$10)+('Input and Output'!B$24*Calculations!$C$5)+('Input and Output'!B$25*Calculations!$C$6)+('Input and Output'!B$26*(IF('Input and Output'!D$7="Detritus",Calculations!$C$4,G7))-(SUM('Input and Output'!B$27:B$32))*H6)) -> 312.7611 | D7: =(('Input and Output'!C$23*'Input and Output'!$B$10)+('Input and Output'!C$24*Calculations!$C$5)+('Input and Output'!C$25*Calculations!$C$6)+('Input and Output'!C$26*(IF('Input and Output'!E$7="Detritus",Calculations!$C$4,H7))-(SUM('Input and Output'!C$27:C$32))*I6)) -> 3279.1523 | E7: =(('Input and Output'!D$23*'Input and Output'!$B$10)+('Input and Output'!D$24*Calculations!$C$5)+('Input and Output'!D$25*Calculations!$C$6)+('Input and Output'!D$26*(IF('Input and Output'!F$7="Detritus",Calculations!$C$4,I7))-(SUM('Input and Output'!D$27:D$32))*J6)) -> 3624.0067 | F7: =(('Input and Output'!E$23*'Input and Output'!$B$10)+('Input and Output'!E$24*Calculations!$C$5)+('Input and Output'!E$25*Calculations!$C$6)+('Input and Output'!E$26*(IF('Input and Output'!G$7="Detritus",Calculations!$C$4,J7))-(SUM('Input and Output'!E$27:E$32))*K6)) -> #N/A | H7: =IF(H$2="",NA(),C7*$B7+H6) -> 130.33021 | I7: =IF(I$2="",NA(),D7*$B7+I6) -> 1366.3989 | J7: =IF(J$2="",NA(),E7*$B7+J6) -> 1513.9059 | K7: =IF(K$2="",NA(),F7*$B7+K6) -> #N/A
A8: 5 | B8: =A8/$B$1 -> 0.20833333 | C8: =(('Input and Output'!B$23*'Input and Output'!$B$10)+('Input and Output'!B$24*Calculations!$C$5)+('Input and Output'!B$25*Calculations!$C$6)+('Input and Output'!B$26*(IF('Input and Output'!D$7="Detritus",Calculations!$C$4,G8))-(SUM('Input and Output'!B$27:B$32))*H7)) -> 312.71084 | D8: =(('Input and Output'!C$23*'Input and Output'!$B$10)+('Input and Output'!C$24*Calculations!$C$5)+('Input and Output'!C$25*Calculations!$C$6)+('Input and Output'!C$26*(IF('Input and Output'!E$7="Detritus",Calculations!$C$4,H8))-(SUM('Input and Output'!C$27:C$32))*I7)) -> 3278.663 | E8: =(('Input and Output'!D$23*'Input and Output'!$B$10)+('Input and Output'!D$24*Calculations!$C$5)+('Input and Output'!D$25*Calculations!$C$6)+('Input and Output'!D$26*(IF('Input and Output'!F$7="Detritus",Calculations!$C$4,I8))-(SUM('Input and Output'!D$27:D$32))*J7)) -> 3607.1101 | F8: =(('Input and Output'!E$23*'Input and Output'!$B$10)+('Input and Output'!E$24*Calculations!$C$5)+('Input and Output'!E$25*Calculations!$C$6)+('Input and Output'!E$26*(IF('Input and Output'!G$7="Detritus",Calculations!$C$4,J8))-(SUM('Input and Output'!E$27:E$32))*K7)) -> #N/A | H8: =IF(H$2="",NA(),C8*$B8+H7) -> 195.4783 | I8: =IF(I$2="",NA(),D8*$B8+I7) -> 2049.4537 | J8: =IF(J$2="",NA(),E8*$B8+J7) -> 2265.3871 | K8: =IF(K$2="",NA(),F8*$B8+K7) -> #N/A
A9: 6 | B9: =A9/$B$1 -> 0.25 | C9: =(('Input and Output'!B$23*'Input and Output'!$B$10)+('Input and Output'!B$24*Calculations!$C$5)+('Input and Output'!B$25*Calculations!$C$6)+('Input and Output'!B$26*(IF('Input and Output'!D$7="Detritus",Calculations!$C$4,G9))-(SUM('Input and Output'!B$27:B$32))*H8)) -> 312.64803 | D9: =(('Input and Output'!C$23*'Input and Output'!$B$10)+('Input and Output'!C$24*Calculations!$C$5)+('Input and Output'!C$25*Calculations!$C$6)+('Input and Output'!C$26*(IF('Input and Output'!E$7="Detritus",Calculations!$C$4,H9))-(SUM('Input and Output'!C$27:C$32))*I8)) -> 3277.9842 | E9: =(('Input and Output'!D$23*'Input and Output'!$B$10)+('Input and Output'!D$24*Calculations!$C$5)+('Input and Output'!D$25*Calculations!$C$6)+('Input and Output'!D$26*(IF('Input and Output'!F$7="Detritus",Calculations!$C$4,I9))-(SUM('Input and Output'!D$27:D$32))*J8)) -> 3585.3345 | F9: =(('Input and Output'!E$23*'Input and Output'!$B$10)+('Input and Output'!E$24*Calculations!$C$5)+('Input and Output'!E$25*Calculations!$C$6)+('Input and Output'!E$26*(IF('Input and Output'!G$7="Detritus",Calculations!$C$4,J9))-(SUM('Input and Output'!E$27:E$32))*K8)) -> #N/A | H9: =IF(H$2="",NA(),C9*$B9+H8) -> 273.64031 | I9: =IF(I$2="",NA(),D9*$B9+I8) -> 2868.9497 | J9: =IF(J$2="",NA(),E9*$B9+J8) -> 3161.7208 | K9: =IF(K$2="",NA(),F9*$B9+K8) -> #N/A
A10: 7 | B10: =A10/$B$1 -> 0.29166667 | C10: =(('Input and Output'!B$23*'Input and Output'!$B$10)+('Input and Output'!B$24*Calculations!$C$5)+('Input and Output'!B$25*Calculations!$C$6)+('Input and Output'!B$26*(IF('Input and Output'!D$7="Detritus",Calculations!$C$4,G10))-(SUM('Input and Output'!B$27:B$32))*H9)) -> 312.57267 | D10: =(('Input and Output'!C$23*'Input and Output'!$B$10)+('Input and Output'!C$24*Calculations!$C$5)+('Input and Output'!C$25*Calculations!$C$6)+('Input and Output'!C$26*(IF('Input and Output'!E$7="Detritus",Calculations!$C$4,H10))-(SUM('Input and Output'!C$27:C$32))*I9)) -> 3277.116 | E10: =(('Input and Output'!D$23*'Input and Output'!$B$10)+('Input and Output'!D$24*Calculations!$C$5)+('Input and Output'!D$25*Calculations!$C$6)+('Input and Output'!D$26*(IF('Input and Output'!F$7="Detritus",Calculations!$C$4,I10))-(SUM('Input and Output'!D$27:D$32))*J9)) -> 3558.8245 | F10: =(('Input and Output'!E$23*'Input and Output'!$B$10)+('Input and Output'!E$24*Calculations!$C$5)+('Input and Output'!E$25*Calculations!$C$6)+('Input and Output'!E$26*(IF('Input and Output'!G$7="Detritus",Calculations!$C$4,J10))-(SUM('Input and Output'!E$27:E$32))*K9)) -> #N/A | H10: =IF(H$2="",NA(),C10*$B10+H9) -> 364.80734 | I10: =IF(I$2="",NA(),D10*$B10+I9) -> 3824.7752 | J10: =IF(J$2="",NA(),E10*$B10+J9) -> 4199.7112 | K10: =IF(K$2="",NA(),F10*$B10+K9) -> #N/A
A11: 8 | B11: =A11/$B$1 -> 0.33333333 | C11: =(('Input and Output'!B$23*'Input and Output'!$B$10)+('Input and Output'!B$24*Calculations!$C$5)+('Input and Output'!B$25*Calculations!$C$6)+('Input and Output'!B$26*(IF('Input and Output'!D$7="Detritus",Calculations!$C$4,G11))-(SUM('Input and Output'!B$27:B$32))*H10)) -> 312.48478 | D11: =(('Input and Output'!C$23*'Input and Output'!$B$10)+('Input and Output'!C$24*Calculations!$C$5)+('Input and Output'!C$25*Calculations!$C$6)+('Input and Output'!C$26*(IF('Input and Output'!E$7="Detritus",Calculations!$C$4,H11))-(SUM('Input and Output'!C$27:C$32))*I10)) -> 3276.0586 | E11: =(('Input and Output'!D$23*'Input and Output'!$B$10)+('Input and Output'!D$24*Calculations!$C$5)+('Input and Output'!D$25*Calculations!$C$6)+('Input and Output'!D$26*(IF('Input and Output'!F$7="Detritus",Calculations!$C$4,I11))-(SUM('Input and Output'!D$27:D$32))*J10)) -> 3527.7558 | F11: =(('Input and Output'!E$23*'Input and Output'!$B$10)+('Input and Output'!E$24*Calculations!$C$5)+('Input and Output'!E$25*Calculations!$C$6)+('Input and Output'!E$26*(IF('Input and Output'!G$7="Detritus",Calculations!$C$4,J11))-(SUM('Input and Output'!E$27:E$32))*K10)) -> #N/A | H11: =IF(H$2="",NA(),C11*$B11+H10) -> 468.96893 | I11: =IF(I$2="",NA(),D11*$B11+I10) -> 4916.7948 | J11: =IF(J$2="",NA(),E11*$B11+J10) -> 5375.6298 | K11: =IF(K$2="",NA(),F11*$B11+K10) -> #N/A
A12: 9 | B12: =A12/$B$1 -> 0.375 | C12: =(('Input and Output'!B$23*'Input and Output'!$B$10)+('Input and Output'!B$24*Calculations!$C$5)+('Input and Output'!B$25*Calculations!$C$6)+('Input and Output'!B$26*(IF('Input and Output'!D$7="Detritus",Calculations!$C$4,G12))-(SUM('Input and Output'!B$27:B$32))*H11)) -> 312.38435 | D12: =(('Input and Output'!C$23*'Input and Output'!$B$10)+('Input and Output'!C$24*Calculations!$C$5)+('Input and Output'!C$25*Calculations!$C$6)+('Input and Output'!C$26*(IF('Input and Output'!E$7="Detritus",Calculations!$C$4,H12))-(SUM('Input and Output'!C$27:C$32))*I11)) -> 3274.8122 | E12: =(('Input and Output'!D$23*'Input and Output'!$B$10)+('Input and Output'!D$24*Calculations!$C$5)+('Input and Output'!D$25*Calculations!$C$6)+('Input and Output'!D$26*(IF('Input and Output'!F$7="Detritus",Calculations!$C$4,I12))-(SUM('Input and Output'!D$27:D$32))*J11)) -> 3492.3334 | F12: =(('Input and Output'!E$23*'Input and Output'!$B$10)+('Input and Output'!E$24*Calculations!$C$5)+('Input and Output'!E$25*Calculations!$C$6)+('Input and Output'!E$26*(IF('Input and Output'!G$7="Detritus",Calculations!$C$4,J12))-(SUM('Input and Output'!E$27:E$32))*K11)) -> #N/A | H12: =IF(H$2="",NA(),C12*$B12+H11) -> 586.11307 | I12: =IF(I$2="",NA(),D12*$B12+I11) -> 6144.8493 | J12: =IF(J$2="",NA(),E12*$B12+J11) -> 6685.2548 | K12: =IF(K$2="",NA(),F12*$B12+K11) -> #N/A
